Workbook

Sheet 8月1日审计
A2: 2026-08-01 MILP审计
A3: 100MW/200MWh，月度份额版。订单由7月31日冻结，8月1日正式执行。
A4: A列为15分钟，B—H价格，I—P状态与选择，Q—W现金，BE—BK为带取值的计算过程。
A8: 时间 Bucharest | B8: DA价格 EUR/MWh | C8: FCR容量价 EUR/(MW·h) | D8: aFRR上容量价 EUR/(MW·h) | E8: aFRR下容量价 EUR/(MW·h) | F8: aFRR上激活价 EUR/MWh | G8: aFRR下激活价 EUR/MWh | H8: FCR激活 未纳入模型 | I8: 起SOC MWh | J8: 末SOC MWh | K8: DA净申报 MW | L8: FCR中标预留 MW | M8: aFRR上中标 MW | N8: aFRR下中标 MW | O8: 上调激活 MWh | P8: 下调激活 MWh | Q8: DA现金 EUR | R8: FCR容量现金 EUR | S8: aFRR上容量现金 EUR | T8: aFRR下容量现金 EUR | U8: aFRR上激活现金 EUR | V8: aFRR下激活现金 EUR | W8: 总现金 EUR | X8: 原账本总现金 EUR | Y8: 现金差异 EUR | Z8: 执行或计划 | AA8: aFRR小时有效 1/0 | AB8: FCR小时有效 1/0 | AC8: 时长h | AD8: FCR月份额 | AE8: aFRR月份额 | AF8: 有效α上 | AG8: 有效α下 | AH8: 系统上采购 MW | AI8: 系统下采购 MW | AJ8: 系统上激活 MWh | AK8: 系统下激活 MWh | AL8: 系统FCR采购 MW | AM8: EFC复算 | AN8: AC充电 MWh | AO8: AC放电 MWh | AP8: 相位复算末SOC MWh | AQ8: SOC差异 MWh | AR8: 汇率 RON/EUR | AS8: 汇率来源日 | AT8: UTC起点 | AU8: DA原生订单ID | AV8: DA原生分钟 | AW8: aFRR门禁原因 | AX8: FCR需求 MW | AY8: aFRR上需求 MW | AZ8: aFRR下需求 MW | BA8: FCR最终容量上限 MW | BB8: aFRR上最终上限 MW | BC8: aFRR下最终上限 MW | BD8: 求解窗口起日 | BE8: DA现金计算过程 | BF8: FCR容量现金计算过程 | BG8: aFRR上容量现金计算过程 | BH8: aFRR下容量现金计算过程 | BI8: aFRR上激活现金计算过程 | BJ8: aFRR下激活现金计算过程 | BK8: 总现金计算过程
A9: =两日求解价格与决策!A9 -> 46235 | B9: =两日求解价格与决策!B9 -> 179.01 | C9: =两日求解价格与决策!C9 -> 66.224535 | D9: =两日求解价格与决策!D9 -> 7.1274751 | E9: =两日求解价格与决策!E9 -> 2.7061536 | F9: =两日求解价格与决策!F9 -> 391.8358 | G9: =两日求解价格与决策!G9 -> 0 | H9: =两日求解价格与决策!H9 -> 未模拟 | ... Y9: =两日求解价格与决策!Y9 -> 0 | Z9: ="正式执行" -> 正式执行 | AA9: =两日求解价格与决策!AA9 -> 1 | AB9: =两日求解价格与决策!AB9 -> 1 | AC9: =两日求解价格与决策!AC9 -> 0.25 | AD9: =两日求解价格与决策!AD9 -> 0.3125 | AE9: =两日求解价格与决策!AE9 -> 0.13714286 | AF9: =两日求解价格与决策!AF9 -> 0.42109714 | AG9: =两日求解价格与决策!AG9 -> 0 | AH9: =两日求解价格与决策!AH9 -> 175 | ... BK9: =两日求解价格与决策!BK9 -> -1074.060000 + 662.245345 + 42.764850 + 16.236922 + 990.005618 + 0.000000 = 637.192736 EUR
A10: =两日求解价格与决策!A10 -> 46235.01 | B10: =两日求解价格与决策!B10 -> 170.12 | C10: =两日求解价格与决策!C10 -> 66.224535 | D10: =两日求解价格与决策!D10 -> 7.1274751 | E10: =两日求解价格与决策!E10 -> 2.7061536 | F10: =两日求解价格与决策!F10 -> 264.63515 | G10: =两日求解价格与决策!G10 -> 0 | H10: =两日求解价格与决策!H10 -> 未模拟 | ... Y10: =两日求解价格与决策!Y10 -> 0 | Z10: ="正式执行" -> 正式执行 | AA10: =两日求解价格与决策!AA10 -> 1 | AB10: =两日求解价格与决策!AB10 -> 1 | AC10: =两日求解价格与决策!AC10 -> 0.25 | AD10: =两日求解价格与决策!AD10 -> 0.3125 | AE10: =两日求解价格与决策!AE10 -> 0.13714286 | AF10: =两日求解价格与决策!AF10 -> 0.35289143 | AG10: =两日求解价格与决策!AG10 -> 0 | AH10: =两日求解价格与决策!AH10 -> 175 | ... BK10: =两日求解价格与决策!BK10 -> 0.000000 + 662.245345 + 42.764850 + 16.236922 + 560.324848 + 0.000000 = 1281.571965 EUR
A11: =两日求解价格与决策!A11 -> 46235.021 | B11: =两日求解价格与决策!B11 -> 167.36 | C11: =两日求解价格与决策!C11 -> 66.224535 | D11: =两日求解价格与决策!D11 -> 7.1274751 | E11: =两日求解价格与决策!E11 -> 2.7061536 | F11: =两日求解价格与决策!F11 -> 422.70215 | G11: =两日求解价格与决策!G11 -> 0 | H11: =两日求解价格与决策!H11 -> 未模拟 | ... Y11: =两日求解价格与决策!Y11 -> 0 | Z11: ="正式执行" -> 正式执行 | AA11: =两日求解价格与决策!AA11 -> 1 | AB11: =两日求解价格与决策!AB11 -> 1 | AC11: =两日求解价格与决策!AC11 -> 0.25 | AD11: =两日求解价格与决策!AD11 -> 0.3125 | AE11: =两日求解价格与决策!AE11 -> 0.13714286 | AF11: =两日求解价格与决策!AF11 -> 0.54525714 | AG11: =两日求解价格与决策!AG11 -> 0 | AH11: =两日求解价格与决策!AH11 -> 175 | ... BK11: =两日求解价格与决策!BK11 -> -1004.160000 + 662.245345 + 42.764850 + 16.236922 + 1382.888205 + 0.000000 = 1099.975322 EUR
A12: =两日求解价格与决策!A12 -> 46235.031 | B12: =两日求解价格与决策!B12 -> 165.13 | C12: =两日求解价格与决策!C12 -> 66.224535 | D12: =两日求解价格与决策!D12 -> 7.1274751 | E12: =两日求解价格与决策!E12 -> 2.7061536 | F12: =两日求解价格与决策!F12 -> 260.51455 | G12: =两日求解价格与决策!G12 -> 76.261125 | H12: =两日求解价格与决策!H12 -> 未模拟 | ... Y12: =两日求解价格与决策!Y12 -> 0 | Z12: ="正式执行" -> 正式执行 | AA12: =两日求解价格与决策!AA12 -> 1 | AB12: =两日求解价格与决策!AB12 -> 1 | AC12: =两日求解价格与决策!AC12 -> 0.25 | AD12: =两日求解价格与决策!AD12 -> 0.3125 | AE12: =两日求解价格与决策!AE12 -> 0.13714286 | AF12: =两日求解价格与决策!AF12 -> 0.31442286 | AG12: =两日求解价格与决策!AG12 -> 0.011337143 | AH12: =两日求解价格与决策!AH12 -> 175 | ... BK12: =两日求解价格与决策!BK12 -> -990.780000 + 662.245345 + 42.764850 + 16.236922 + 491.470375 + -5.187500 = 216.749993 EUR
A13: =两日求解价格与决策!A13 -> 46235.042 | B13: =两日求解价格与决策!B13 -> 184.32 | C13: =两日求解价格与决策!C13 -> 66.224535 | D13: =两日求解价格与决策!D13 -> 7.1274751 | E13: =两日求解价格与决策!E13 -> 2.7061536 | F13: =两日求解价格与决策!F13 -> 171.08894 | G13: =两日求解价格与决策!G13 -> 74.70947 | H13: =两日求解价格与决策!H13 -> 未模拟 | ... Y13: =两日求解价格与决策!Y13 -> 0 | Z13: ="正式执行" -> 正式执行 | AA13: =两日求解价格与决策!AA13 -> 1 | AB13: =两日求解价格与决策!AB13 -> 1 | AC13: =两日求解价格与决策!AC13 -> 0.25 | AD13: =两日求解价格与决策!AD13 -> 0.3125 | AE13: =两日求解价格与决策!AE13 -> 0.13714286 | AF13: =两日求解价格与决策!AF13 -> 0.024434286 | AG13: =两日求解价格与决策!AG13 -> 0.040342857 | AH13: =两日求解价格与决策!AH13 -> 175 | ... BK13: =两日求解价格与决策!BK13 -> 937.194033 + 662.245345 + 42.764850 + 16.236922 + 25.082616 + -18.083961 = 1665.439807 EUR
A14: =两日求解价格与决策!A14 -> 46235.052 | B14: =两日求解价格与决策!B14 -> 174.23 | C14: =两日求解价格与决策!C14 -> 66.224535 | D14: =两日求解价格与决策!D14 -> 7.1274751 | E14: =两日求解价格与决策!E14 -> 2.7061536 | F14: =两日求解价格与决策!F14 -> 190.53685 | G14: =两日求解价格与决策!G14 -> 0 | H14: =两日求解价格与决策!H14 -> 未模拟 | ... Y14: =两日求解价格与决策!Y14 -> 0 | Z14: ="正式执行" -> 正式执行 | AA14: =两日求解价格与决策!AA14 -> 1 | AB14: =两日求解价格与决策!AB14 -> 1 | AC14: =两日求解价格与决策!AC14 -> 0.25 | AD14: =两日求解价格与决策!AD14 -> 0.3125 | AE14: =两日求解价格与决策!AE14 -> 0.13714286 | AF14: =两日求解价格与决策!AF14 -> 0.12907429 | AG14: =两日求解价格与决策!AG14 -> 0 | AH14: =两日求解价格与决策!AH14 -> 175 | ... BK14: =两日求解价格与决策!BK14 -> 0.000000 + 662.245345 + 42.764850 + 16.236922 + 147.560445 + 0.000000 = 868.807563 EUR
A15: =两日求解价格与决策!A15 -> 46235.062 | B15: =两日求解价格与决策!B15 -> 165.3 | C15: =两日求解价格与决策!C15 -> 66.224535 | D15: =两日求解价格与决策!D15 -> 7.1274751 | E15: =两日求解价格与决策!E15 -> 2.7061536 | F15: =两日求解价格与决策!F15 -> 181.55185 | G15: =两日求解价格与决策!G15 -> 0 | H15: =两日求解价格与决策!H15 -> 未模拟 | ... Y15: =两日求解价格与决策!Y15 -> 0 | Z15: ="正式执行" -> 正式执行 | AA15: =两日求解价格与决策!AA15 -> 1 | AB15: =两日求解价格与决策!AB15 -> 1 | AC15: =两日求解价格与决策!AC15 -> 0.25 | AD15: =两日求解价格与决策!AD15 -> 0.3125 | AE15: =两日求解价格与决策!AE15 -> 0.13714286 | AF15: =两日求解价格与决策!AF15 -> 0.14537143 | AG15: =两日求解价格与决策!AG15 -> 0 | AH15: =两日求解价格与决策!AH15 -> 175 | ... BK15: =两日求解价格与决策!BK15 -> 0.000000 + 662.245345 + 42.764850 + 16.236922 + 158.354707 + 0.000000 = 879.601825 EUR
A16: =两日求解价格与决策!A16 -> 46235.073 | B16: =两日求解价格与决策!B16 -> 157.23 | C16: =两日求解价格与决策!C16 -> 66.224535 | D16: =两日求解价格与决策!D16 -> 7.1274751 | E16: =两日求解价格与决策!E16 -> 2.7061536 | F16: =两日求解价格与决策!F16 -> 190.08785 | G16: =两日求解价格与决策!G16 -> 0 | H16: =两日求解价格与决策!H16 -> 未模拟 | ... Y16: =两日求解价格与决策!Y16 -> 0 | Z16: ="正式执行" -> 正式执行 | AA16: =两日求解价格与决策!AA16 -> 1 | AB16: =两日求解价格与决策!AB16 -> 1 | AC16: =两日求解价格与决策!AC16 -> 0.25 | AD16: =两日求解价格与决策!AD16 -> 0.3125 | AE16: =两日求解价格与决策!AE16 -> 0.13714286 | AF16: =两日求解价格与决策!AF16 -> 0.14626286 | AG16: =两日求解价格与决策!AG16 -> 0 | AH16: =两日求解价格与决策!AH16 -> 175 | ... BK16: =两日求解价格与决策!BK16 -> -943.380000 + 662.245345 + 42.764850 + 16.236922 + 166.816756 + 0.000000 = -55.316126 EUR
A17: =两日求解价格与决策!A17 -> 46235.083 | B17: =两日求解价格与决策!B17 -> 170.44 | C17: =两日求解价格与决策!C17 -> 66.224535 | D17: =两日求解价格与决策!D17 -> 7.1274751 | E17: =两日求解价格与决策!E17 -> 2.7061536 | F17: =两日求解价格与决策!F17 -> 227.42973 | G17: =两日求解价格与决策!G17 -> 0 | H17: =两日求解价格与决策!H17 -> 未模拟 | ... Y17: =两日求解价格与决策!Y17 -> 0 | Z17: ="正式执行" -> 正式执行 | AA17: =两日求解价格与决策!AA17 -> 1 | AB17: =两日求解价格与决策!AB17 -> 1 | AC17: =两日求解价格与决策!AC17 -> 0.25 | AD17: =两日求解价格与决策!AD17 -> 0.3125 | AE17: =两日求解价格与决策!AE17 -> 0.13714286 | AF17: =两日求解价格与决策!AF17 -> 0.33814857 | AG17: =两日求解价格与决策!AG17 -> 0 | AH17: =两日求解价格与决策!AH17 -> 175 | ... BK17: =两日求解价格与决策!BK17 -> 0.000000 + 662.245345 + 42.764850 + 16.236922 + 461.430221 + 0.000000 = 1182.677339 EUR
A18: =两日求解价格与决策!A18 -> 46235.094 | B18: =两日求解价格与决策!B18 -> 169.42 | C18: =两日求解价格与决策!C18 -> 66.224535 | D18: =两日求解价格与决策!D18 -> 7.1274751 | E18: =两日求解价格与决策!E18 -> 2.7061536 | F18: =两日求解价格与决策!F18 -> 236.08846 | G18: =两日求解价格与决策!G18 -> 0 | H18: =两日求解价格与决策!H18 -> 未模拟 | ... Y18: =两日求解价格与决策!Y18 -> 0 | Z18: ="正式执行" -> 正式执行 | AA18: =两日求解价格与决策!AA18 -> 1 | AB18: =两日求解价格与决策!AB18 -> 1 | AC18: =两日求解价格与决策!AC18 -> 0.25 | AD18: =两日求解价格与决策!AD18 -> 0.3125 | AE18: =两日求解价格与决策!AE18 -> 0.13714286 | AF18: =两日求解价格与决策!AF18 -> 0.3504 | AG18: =两日求解价格与决策!AG18 -> 0 | AH18: =两日求解价格与决策!AH18 -> 175 | ... BK18: =两日求解价格与决策!BK18 -> 0.000000 + 662.245345 + 42.764850 + 16.236922 + 496.352388 + 0.000000 = 1217.599505 EUR
A19: =两日求解价格与决策!A19 -> 46235.104 | B19: =两日求解价格与决策!B19 -> 158.09 | C19: =两日求解价格与决策!C19 -> 66.224535 | D19: =两日求解价格与决策!D19 -> 7.1274751 | E19: =两日求解价格与决策!E19 -> 2.7061536 | F19: =两日求解价格与决策!F19 -> 179.29545 | G19: =两日求解价格与决策!G19 -> 0 | H19: =两日求解价格与决策!H19 -> 未模拟 | ... Y19: =两日求解价格与决策!Y19 -> 0 | Z19: ="正式执行" -> 正式执行 | AA19: =两日求解价格与决策!AA19 -> 1 | AB19: =两日求解价格与决策!AB19 -> 1 | AC19: =两日求解价格与决策!AC19 -> 0.25 | AD19: =两日求解价格与决策!AD19 -> 0.3125 | AE19: =两日求解价格与决策!AE19 -> 0.13714286 | AF19: =两日求解价格与决策!AF19 -> 0.040845714 | AG19: =两日求解价格与决策!AG19 -> 0 | AH19: =两日求解价格与决策!AH19 -> 175 | ... BK19: =两日求解价格与决策!BK19 -> -43.031250 + 662.245345 + 42.764850 + 16.236922 + 43.940704 + 0.000000 = 722.156571 EUR
A20: =两日求解价格与决策!A20 -> 46235.115 | B20: =两日求解价格与决策!B20 -> 156.91 | C20: =两日求解价格与决策!C20 -> 66.224535 | D20: =两日求解价格与决策!D20 -> 7.1274751 | E20: =两日求解价格与决策!E20 -> 2.7061536 | F20: =两日求解价格与决策!F20 -> 170.86159 | G20: =两日求解价格与决策!G20 -> 0 | H20: =两日求解价格与决策!H20 -> 未模拟 | ... Y20: =两日求解价格与决策!Y20 -> 0 | Z20: ="正式执行" -> 正式执行 | AA20: =两日求解价格与决策!AA20 -> 1 | AB20: =两日求解价格与决策!AB20 -> 1 | AC20: =两日求解价格与决策!AC20 -> 0.25 | AD20: =两日求解价格与决策!AD20 -> 0.3125 | AE20: =两日求解价格与决策!AE20 -> 0.13714286 | AF20: =两日求解价格与决策!AF20 -> 0.0448 | AG20: =两日求解价格与决策!AG20 -> 0 | AH20: =两日求解价格与决策!AH20 -> 175 | ... BK20: =两日求解价格与决策!BK20 -> -167.503950 + 662.245345 + 42.764850 + 16.236922 + 45.927594 + 0.000000 = 599.670761 EUR
... A104: =两日求解价格与决策!A104 -> 46235.99 | B104: =两日求解价格与决策!B104 -> 169.1 | C104: =两日求解价格与决策!C104 -> 66.224535 | D104: =两日求解价格与决策!D104 -> 7.1274751 | E104: =两日求解价格与决策!E104 -> 2.5937149 | F104: =两日求解价格与决策!F104 -> 198.77747 | G104: =两日求解价格与决策!G104 -> 77.182551 | H104: =两日求解价格与决策!H104 -> 未模拟 | ... Y104: =两日求解价格与决策!Y104 -> 0 | Z104: ="正式执行" -> 正式执行 | AA104: =两日求解价格与决策!AA104 -> 1 | AB104: =两日求解价格与决策!AB104 -> 1 | AC104: =两日求解价格与决策!AC104 -> 0.25 | AD104: =两日求解价格与决策!AD104 -> 0.3125 | AE104: =两日求解价格与决策!AE104 -> 0.13714286 | AF104: =两日求解价格与决策!AF104 -> 0.048937143 | AG104: =两日求解价格与决策!AG104 -> 0.00288 | AH104: =两日求解价格与决策!AH104 -> 175 | ... BK104: =两日求解价格与决策!BK104 -> 0.000000 + 662.245345 + 42.764850 + 15.562289 + 58.365608 + -1.333714 = 777.604378 EUR
A106: 当日现金及电量合计 | O106: =SUM(O9:O104) -> 72.037554 | P106: =SUM(P9:P104) -> 40.595177 | Q106: =SUM(Q9:Q104) -> 18846.745 | R106: =SUM(R9:R104) -> 63575.553 | S106: =SUM(S9:S104) -> 2990.1873 | T106: =SUM(T9:T104) -> 1894.1284 | U106: =SUM(U9:U104) -> 17712.625 | V106: =SUM(V9:V104) -> 2519.1835 | ... X106: =SUM(X9:X104) -> 107538.42
A109: 承接前日末SOC MWh | B109: =订单与窗口!C6 -> 31.73913
A110: 当日期末SOC MWh | B110: =J104 -> 31.73913
A112: 两天正式现金合计 EUR | B112: ='8月1日审计'!W106+'8月2日审计'!W106 -> 208618.55
A115: 容量现金=中标预留MW×价格×时长；月份额只限制MW，不再次乘现金。
A116: FCR对称容量只计一次；激活电量已为MWh，不再乘0.25小时。
A117: 逐行现金公式在Q—W，含取值的过程在BE—BK；显示精度不改变底层数值。

Sheet 8月2日审计
A2: 2026-08-02 MILP审计
A3: 100MW/200MWh，月度份额版。订单由8月1日冻结，8月2日正式执行。
A4: A列为15分钟，B—H价格，I—P状态与选择，Q—W现金，BE—BK为带取值的计算过程。
A8: 时间 Bucharest | B8: DA价格 EUR/MWh | C8: FCR容量价 EUR/(MW·h) | D8: aFRR上容量价 EUR/(MW·h) | E8: aFRR下容量价 EUR/(MW·h) | F8: aFRR上激活价 EUR/MWh | G8: aFRR下激活价 EUR/MWh | H8: FCR激活 未纳入模型 | I8: 起SOC MWh | J8: 末SOC MWh | K8: DA净申报 MW | L8: FCR中标预留 MW | M8: aFRR上中标 MW | N8: aFRR下中标 MW | O8: 上调激活 MWh | P8: 下调激活 MWh | Q8: DA现金 EUR | R8: FCR容量现金 EUR | S8: aFRR上容量现金 EUR | T8: aFRR下容量现金 EUR | U8: aFRR上激活现金 EUR | V8: aFRR下激活现金 EUR | W8: 总现金 EUR | X8: 原账本总现金 EUR | Y8: 现金差异 EUR | Z8: 执行或计划 | AA8: aFRR小时有效 1/0 | AB8: FCR小时有效 1/0 | AC8: 时长h | AD8: FCR月份额 | AE8: aFRR月份额 | AF8: 有效α上 | AG8: 有效α下 | AH8: 系统上采购 MW | AI8: 系统下采购 MW | AJ8: 系统上激活 MWh | AK8: 系统下激活 MWh | AL8: 系统FCR采购 MW | AM8: EFC复算 | AN8: AC充电 MWh | AO8: AC放电 MWh | AP8: 相位复算末SOC MWh | AQ8: SOC差异 MWh | AR8: 汇率 RON/EUR | AS8: 汇率来源日 | AT8: UTC起点 | AU8: DA原生订单ID | AV8: DA原生分钟 | AW8: aFRR门禁原因 | AX8: FCR需求 MW | AY8: aFRR上需求 MW | AZ8: aFRR下需求 MW | BA8: FCR最终容量上限 MW | BB8: aFRR上最终上限 MW | BC8: aFRR下最终上限 MW | BD8: 求解窗口起日 | BE8: DA现金计算过程 | BF8: FCR容量现金计算过程 | BG8: aFRR上容量现金计算过程 | BH8: aFRR下容量现金计算过程 | BI8: aFRR上激活现金计算过程 | BJ8: aFRR下激活现金计算过程 | BK8: 总现金计算过程
A9: =两日求解价格与决策!A201 -> 46236 | B9: =两日求解价格与决策!B201 -> 172.11 | C9: =两日求解价格与决策!C201 -> 66.224535 | D9: =两日求解价格与决策!D201 -> 7.1274751 | E9: =两日求解价格与决策!E201 -> 2.7061536 | F9: =两日求解价格与决策!F201 -> 184.1103 | G9: =两日求解价格与决策!G201 -> 77.182551 | H9: =两日求解价格与决策!H201 -> 未模拟 | ... Y9: =两日求解价格与决策!Y201 -> 0 | Z9: ="正式执行" -> 正式执行 | AA9: =两日求解价格与决策!AA201 -> 1 | AB9: =两日求解价格与决策!AB201 -> 1 | AC9: =两日求解价格与决策!AC201 -> 0.25 | AD9: =两日求解价格与决策!AD201 -> 0.3125 | AE9: =两日求解价格与决策!AE201 -> 0.13714286 | AF9: =两日求解价格与决策!AF201 -> 0.05232 | AG9: =两日求解价格与决策!AG201 -> 0.0080685714 | AH9: =两日求解价格与决策!AH201 -> 175 | ... BK9: =两日求解价格与决策!BK201 -> -794.202771 + 662.245345 + 42.764850 + 16.236922 + 57.795907 + -3.736518 = -18.896264 EUR
A10: =两日求解价格与决策!A202 -> 46236.01 | B10: =两日求解价格与决策!B202 -> 171.94 | C10: =两日求解价格与决策!C202 -> 66.224535 | D10: =两日求解价格与决策!D202 -> 7.1274751 | E10: =两日求解价格与决策!E202 -> 2.7061536 | F10: =两日求解价格与决策!F202 -> 0 | G10: =两日求解价格与决策!G202 -> 70.316734 | H10: =两日求解价格与决策!H202 -> 未模拟 | ... Y10: =两日求解价格与决策!Y202 -> 0 | Z10: ="正式执行" -> 正式执行 | AA10: =两日求解价格与决策!AA202 -> 1 | AB10: =两日求解价格与决策!AB202 -> 1 | AC10: =两日求解价格与决策!AC202 -> 0.25 | AD10: =两日求解价格与决策!AD202 -> 0.3125 | AE10: =两日求解价格与决策!AE202 -> 0.13714286 | AF10: =两日求解价格与决策!AF202 -> 0 | AG10: =两日求解价格与决策!AG202 -> 0.12836571 | AH10: =两日求解价格与决策!AH202 -> 175 | ... BK10: =两日求解价格与决策!BK202 -> 0.000000 + 662.245345 + 42.764850 + 16.236922 + 0.000000 + -54.157547 = 667.089571 EUR
A11: =两日求解价格与决策!A203 -> 46236.021 | B11: =两日求解价格与决策!B203 -> 171.23 | C11: =两日求解价格与决策!C203 -> 66.224535 | D11: =两日求解价格与决策!D203 -> 7.1274751 | E11: =两日求解价格与决策!E203 -> 2.7061536 | F11: =两日求解价格与决策!F203 -> 176.42483 | G11: =两日求解价格与决策!G203 -> 70.125588 | H11: =两日求解价格与决策!H203 -> 未模拟 | ... Y11: =两日求解价格与决策!Y203 -> 0 | Z11: ="正式执行" -> 正式执行 | AA11: =两日求解价格与决策!AA203 -> 1 | AB11: =两日求解价格与决策!AB203 -> 1 | AC11: =两日求解价格与决策!AC203 -> 0.25 | AD11: =两日求解价格与决策!AD203 -> 0.3125 | AE11: =两日求解价格与决策!AE203 -> 0.13714286 | AF11: =两日求解价格与决策!AF203 -> 0.019908571 | AG11: =两日求解价格与决策!AG203 -> 0.02832 | AH11: =两日求解价格与决策!AH203 -> 175 | ... BK11: =两日求解价格与决策!BK203 -> 0.000000 + 662.245345 + 42.764850 + 16.236922 + 21.074198 + -11.915740 = 730.405575 EUR
A12: =两日求解价格与决策!A204 -> 46236.031 | B12: =两日求解价格与决策!B204 -> 164.72 | C12: =两日求解价格与决策!C204 -> 66.224535 | D12: =两日求解价格与决策!D204 -> 7.1274751 | E12: =两日求解价格与决策!E204 -> 2.7061536 | F12: =两日求解价格与决策!F204 -> 157.46479 | G12: =两日求解价格与决策!G204 -> 76.985497 | H12: =两日求解价格与决策!H204 -> 未模拟 | ... Y12: =两日求解价格与决策!Y204 -> 0 | Z12: ="正式执行" -> 正式执行 | AA12: =两日求解价格与决策!AA204 -> 1 | AB12: =两日求解价格与决策!AB204 -> 1 | AC12: =两日求解价格与决策!AC204 -> 0.25 | AD12: =两日求解价格与决策!AD204 -> 0.3125 | AE12: =两日求解价格与决策!AE204 -> 0.13714286 | AF12: =两日求解价格与决策!AF204 -> 0.00336 | AG12: =两日求解价格与决策!AG204 -> 0.023085714 | AH12: =两日求解价格与决策!AH204 -> 175 | ... BK12: =两日求解价格与决策!BK204 -> 0.000000 + 662.245345 + 42.764850 + 16.236922 + 3.174490 + -10.663591 = 713.758017 EUR
A13: =两日求解价格与决策!A205 -> 46236.042 | B13: =两日求解价格与决策!B205 -> 189.01 | C13: =两日求解价格与决策!C205 -> 66.224535 | D13: =两日求解价格与决策!D205 -> 7.1274751 | E13: =两日求解价格与决策!E205 -> 2.7061536 | F13: =两日求解价格与决策!F205 -> 0 | G13: =两日求解价格与决策!G205 -> 76.829989 | H13: =两日求解价格与决策!H205 -> 未模拟 | ... Y13: =两日求解价格与决策!Y205 -> 0 | Z13: ="正式执行" -> 正式执行 | AA13: =两日求解价格与决策!AA205 -> 1 | AB13: =两日求解价格与决策!AB205 -> 1 | AC13: =两日求解价格与决策!AC205 -> 0.25 | AD13: =两日求解价格与决策!AD205 -> 0.3125 | AE13: =两日求解价格与决策!AE205 -> 0.13714286 | AF13: =两日求解价格与决策!AF205 -> 0 | AG13: =两日求解价格与决策!AG205 -> 0.14333714 | AH13: =两日求解价格与决策!AH205 -> 175 | ... BK13: =两日求解价格与决策!BK205 -> 999.396879 + 662.245345 + 42.764850 + 16.236922 + 0.000000 + -66.075546 = 1654.568450 EUR
A14: =两日求解价格与决策!A206 -> 46236.052 | B14: =两日求解价格与决策!B206 -> 171.26 | C14: =两日求解价格与决策!C206 -> 66.224535 | D14: =两日求解价格与决策!D206 -> 7.1274751 | E14: =两日求解价格与决策!E206 -> 2.7061536 | F14: =两日求解价格与决策!F206 -> 152.45936 | G14: =两日求解价格与决策!G206 -> 77.033713 | H14: =两日求解价格与决策!H206 -> 未模拟 | ... Y14: =两日求解价格与决策!Y206 -> 0 | Z14: ="正式执行" -> 正式执行 | AA14: =两日求解价格与决策!AA206 -> 1 | AB14: =两日求解价格与决策!AB206 -> 1 | AC14: =两日求解价格与决策!AC206 -> 0.25 | AD14: =两日求解价格与决策!AD206 -> 0.3125 | AE14: =两日求解价格与决策!AE206 -> 0.13714286 | AF14: =两日求解价格与决策!AF206 -> 9.1428571e-05 | AG14: =两日求解价格与决策!AG206 -> 0.027748571 | AH14: =两日求解价格与决策!AH206 -> 175 | ... BK14: =两日求解价格与决策!BK206 -> 0.000000 + 662.245345 + 42.764850 + 16.236922 + 0.083635 + -12.825453 = 708.505300 EUR
A15: =两日求解价格与决策!A207 -> 46236.062 | B15: =两日求解价格与决策!B207 -> 161.1 | C15: =两日求解价格与决策!C207 -> 66.224535 | D15: =两日求解价格与决策!D207 -> 7.1274751 | E15: =两日求解价格与决策!E207 -> 2.7061536 | F15: =两日求解价格与决策!F207 -> 152.45936 | G15: =两日求解价格与决策!G207 -> 77.182551 | H15: =两日求解价格与决策!H207 -> 未模拟 | ... Y15: =两日求解价格与决策!Y207 -> 0 | Z15: ="正式执行" -> 正式执行 | AA15: =两日求解价格与决策!AA207 -> 1 | AB15: =两日求解价格与决策!AB207 -> 1 | AC15: =两日求解价格与决策!AC207 -> 0.25 | AD15: =两日求解价格与决策!AD207 -> 0.3125 | AE15: =两日求解价格与决策!AE207 -> 0.13714286 | AF15: =两日求解价格与决策!AF207 -> 0.00208 | AG15: =两日求解价格与决策!AG207 -> 0.032708571 | AH15: =两日求解价格与决策!AH207 -> 175 | ... BK15: =两日求解价格与决策!BK207 -> 0.000000 + 662.245345 + 42.764850 + 16.236922 + 1.902693 + -15.147186 = 708.002624 EUR
A16: =两日求解价格与决策!A208 -> 46236.073 | B16: =两日求解价格与决策!B208 -> 160.43 | C16: =两日求解价格与决策!C208 -> 66.224535 | D16: =两日求解价格与决策!D208 -> 7.1274751 | E16: =两日求解价格与决策!E208 -> 2.7061536 | F16: =两日求解价格与决策!F208 -> 165.00619 | G16: =两日求解价格与决策!G208 -> 77.182551 | H16: =两日求解价格与决策!H208 -> 未模拟 | ... Y16: =两日求解价格与决策!Y208 -> 0 | Z16: ="正式执行" -> 正式执行 | AA16: =两日求解价格与决策!AA208 -> 1 | AB16: =两日求解价格与决策!AB208 -> 1 | AC16: =两日求解价格与决策!AC208 -> 0.25 | AD16: =两日求解价格与决策!AD208 -> 0.3125 | AE16: =两日求解价格与决策!AE208 -> 0.13714286 | AF16: =两日求解价格与决策!AF208 -> 0.00464 | AG16: =两日求解价格与决策!AG208 -> 0.0104 | AH16: =两日求解价格与决策!AH208 -> 175 | ... BK16: =两日求解价格与决策!BK208 -> 0.000000 + 662.245345 + 42.764850 + 16.236922 + 4.593772 + -4.816191 = 721.024699 EUR
A17: =两日求解价格与决策!A209 -> 46236.083 | B17: =两日求解价格与决策!B209 -> 160.86 | C17: =两日求解价格与决策!C209 -> 66.224535 | D17: =两日求解价格与决策!D209 -> 7.1274751 | E17: =两日求解价格与决策!E209 -> 2.7061536 | F17: =两日求解价格与决策!F209 -> 178.91716 | G17: =两日求解价格与决策!G209 -> 0 | H17: =两日求解价格与决策!H209 -> 未模拟 | ... Y17: =两日求解价格与决策!Y209 -> 0 | Z17: ="正式执行" -> 正式执行 | AA17: =两日求解价格与决策!AA209 -> 1 | AB17: =两日求解价格与决策!AB209 -> 1 | AC17: =两日求解价格与决策!AC209 -> 0.25 | AD17: =两日求解价格与决策!AD209 -> 0.3125 | AE17: =两日求解价格与决策!AE209 -> 0.13714286 | AF17: =两日求解价格与决策!AF209 -> 0.050034286 | AG17: =两日求解价格与决策!AG209 -> 0 | AH17: =两日求解价格与决策!AH209 -> 175 | ... BK17: =两日求解价格与决策!BK209 -> -7.248674 + 662.245345 + 42.764850 + 16.236922 + 53.711953 + 0.000000 = 767.710397 EUR
A18: =两日求解价格与决策!A210 -> 46236.094 | B18: =两日求解价格与决策!B210 -> 156.81 | C18: =两日求解价格与决策!C210 -> 66.224535 | D18: =两日求解价格与决策!D210 -> 7.1274751 | E18: =两日求解价格与决策!E210 -> 2.7061536 | F18: =两日求解价格与决策!F210 -> 171.4133 | G18: =两日求解价格与决策!G210 -> 76.945667 | H18: =两日求解价格与决策!H210 -> 未模拟 | ... Y18: =两日求解价格与决策!Y210 -> 0 | Z18: ="正式执行" -> 正式执行 | AA18: =两日求解价格与决策!AA210 -> 1 | AB18: =两日求解价格与决策!AB210 -> 1 | AC18: =两日求解价格与决策!AC210 -> 0.25 | AD18: =两日求解价格与决策!AD210 -> 0.3125 | AE18: =两日求解价格与决策!AE210 -> 0.13714286 | AF18: =两日求解价格与决策!AF210 -> 0.062857143 | AG18: =两日求解价格与决策!AG210 -> 0.030742857 | AH18: =两日求解价格与决策!AH210 -> 175 | ... BK18: =两日求解价格与决策!BK210 -> -288.935452 + 662.245345 + 42.764850 + 16.236922 + 64.647301 + -14.193178 = 482.765788 EUR
A19: =两日求解价格与决策!A211 -> 46236.104 | B19: =两日求解价格与决策!B211 -> 162.01 | C19: =两日求解价格与决策!C211 -> 66.224535 | D19: =两日求解价格与决策!D211 -> 7.1274751 | E19: =两日求解价格与决策!E211 -> 2.7061536 | F19: =两日求解价格与决策!F211 -> 171.25703 | G19: =两日求解价格与决策!G211 -> 77.182551 | H19: =两日求解价格与决策!H211 -> 未模拟 | ... Y19: =两日求解价格与决策!Y211 -> 0 | Z19: ="正式执行" -> 正式执行 | AA19: =两日求解价格与决策!AA211 -> 1 | AB19: =两日求解价格与决策!AB211 -> 1 | AC19: =两日求解价格与决策!AC211 -> 0.25 | AD19: =两日求解价格与决策!AD211 -> 0.3125 | AE19: =两日求解价格与决策!AE211 -> 0.13714286 | AF19: =两日求解价格与决策!AF211 -> 0.095771429 | AG19: =两日求解价格与决策!AG211 -> 0.00038857143 | AH19: =两日求解价格与决策!AH211 -> 175 | ... BK19: =两日求解价格与决策!BK211 -> 0.000000 + 662.245345 + 42.764850 + 16.236922 + 98.409181 + -0.179946 = 819.476353 EUR
A20: =两日求解价格与决策!A212 -> 46236.115 | B20: =两日求解价格与决策!B212 -> 160.5 | C20: =两日求解价格与决策!C212 -> 66.224535 | D20: =两日求解价格与决策!D212 -> 7.1274751 | E20: =两日求解价格与决策!E212 -> 2.7061536 | F20: =两日求解价格与决策!F212 -> 161.2334 | G20: =两日求解价格与决策!G212 -> 0 | H20: =两日求解价格与决策!H212 -> 未模拟 | ... Y20: =两日求解价格与决策!Y212 -> 0 | Z20: ="正式执行" -> 正式执行 | AA20: =两日求解价格与决策!AA212 -> 1 | AB20: =两日求解价格与决策!AB212 -> 1 | AC20: =两日求解价格与决策!AC212 -> 0.25 | AD20: =两日求解价格与决策!AD212 -> 0.3125 | AE20: =两日求解价格与决策!AE212 -> 0.13714286 | AF20: =两日求解价格与决策!AF212 -> 0.00752 | AG20: =两日求解价格与决策!AG212 -> 0 | AH20: =两日求解价格与决策!AH212 -> 175 | ... BK20: =两日求解价格与决策!BK212 -> 0.000000 + 662.245345 + 42.764850 + 16.236922 + 7.274851 + 0.000000 = 728.521968 EUR
... A104: =两日求解价格与决策!A296 -> 46236.99 | B104: =两日求解价格与决策!B296 -> 183.75 | C104: =两日求解价格与决策!C296 -> 66.224535 | D104: =两日求解价格与决策!D296 -> 7.1274751 | E104: =两日求解价格与决策!E296 -> 2.5937149 | F104: =两日求解价格与决策!F296 -> 218.7485 | G104: =两日求解价格与决策!G296 -> 76.420254 | H104: =两日求解价格与决策!H296 -> 未模拟 | ... Y104: =两日求解价格与决策!Y296 -> 0 | Z104: ="正式执行" -> 正式执行 | AA104: =两日求解价格与决策!AA296 -> 1 | AB104: =两日求解价格与决策!AB296 -> 1 | AC104: =两日求解价格与决策!AC296 -> 0.25 | AD104: =两日求解价格与决策!AD296 -> 0.3125 | AE104: =两日求解价格与决策!AE296 -> 0.13714286 | AF104: =两日求解价格与决策!AF296 -> 0.14198857 | AG104: =两日求解价格与决策!AG296 -> 0.00096 | AH104: =两日求解价格与决策!AH296 -> 175 | ... BK104: =两日求解价格与决策!BK296 -> 0.000000 + 662.245345 + 42.764850 + 15.562289 + 186.358721 + -0.440181 = 906.491026 EUR
A106: 当日现金及电量合计 | O106: =SUM(O9:O104) -> 48.081737 | P106: =SUM(P9:P104) -> 53.256686 | Q106: =SUM(Q9:Q104) -> 22387.47 | R106: =SUM(R9:R104) -> 61841.328 | S106: =SUM(S9:S104) -> 3527.6199 | T106: =SUM(T9:T104) -> 2074.8957 | U106: =SUM(U9:U104) -> 9593.7193 | V106: =SUM(V9:V104) -> 1655.097 | ... X106: =SUM(X9:X104) -> 101080.13
A109: 承接前日末SOC MWh | B109: =订单与窗口!C7 -> 31.73913
A110: 当日期末SOC MWh | B110: =J104 -> 31.73913
A112: 两天正式现金合计 EUR | B112: ='8月1日审计'!W106+'8月2日审计'!W106 -> 208618.55
A115: 容量现金=中标预留MW×价格×时长；月份额只限制MW，不再次乘现金。
A116: FCR对称容量只计一次；激活电量已为MWh，不再乘0.25小时。
A117: 逐行现金公式在Q—W，含取值的过程在BE—BK；显示精度不改变底层数值。

Sheet 两日求解价格与决策
A2: 两次MILP求解的价格、决策与现金
A3: 首192行：8月1日求解，8月1日执行及8月2日冻结计划；后192行：8月2日求解及8月3日计划。
A4: 六类现金在本表通过Excel公式计算，日审计表链接执行部分。8月3日不计入两天现金。
J5: 1hr
J6: =40*66 -> 2640
A8: 时间 Bucharest | B8: DA价格 EUR/MWh | C8: FCR容量价 EUR/(MW·h) | D8: aFRR上容量价 EUR/(MW·h) | E8: aFRR下容量价 EUR/(MW·h) | F8: aFRR上激活价 EUR/MWh | G8: aFRR下激活价 EUR/MWh | H8: FCR激活 未纳入模型 | I8: 起SOC MWh | J8: 末SOC MWh | K8: DA净申报 MW | L8: FCR中标预留 MW | M8: aFRR上中标 MW | N8: aFRR下中标 MW | O8: 上调激活 MWh | P8: 下调激活 MWh | Q8: DA现金 EUR | R8: FCR容量现金 EUR | S8: aFRR上容量现金 EUR | T8: aFRR下容量现金 EUR | U8: aFRR上激活现金 EUR | V8: aFRR下激活现金 EUR | W8: 总现金 EUR | X8: 原账本总现金 EUR | Y8: 现金差异 EUR | Z8: 执行或计划 | AA8: aFRR小时有效 1/0 | AB8: FCR小时有效 1/0 | AC8: 时长h | AD8: FCR月份额 | AE8: aFRR月份额 | AF8: 有效α上 | AG8: 有效α下 | AH8: 系统上采购 MW | AI8: 系统下采购 MW | AJ8: 系统上激活 MWh | AK8: 系统下激活 MWh | AL8: 系统FCR采购 MW | AM8: EFC复算 | AN8: AC充电 MWh | AO8: AC放电 MWh | AP8: 相位复算末SOC MWh | AQ8: SOC差异 MWh | AR8: 汇率 RON/EUR | AS8: 汇率来源日 | AT8: UTC起点 | AU8: DA原生订单ID | AV8: DA原生分钟 | AW8: aFRR门禁原因 | AX8: FCR需求 MW | AY8: aFRR上需求 MW | AZ8: aFRR下需求 MW | BA8: FCR最终容量上限 MW | BB8: aFRR上最终上限 MW | BC8: aFRR下最终上限 MW | BD8: 求解窗口起日 | BE8: DA现金计算过程 | BF8: FCR容量现金计算过程 | BG8: aFRR上容量现金计算过程 | BH8: aFRR下容量现金计算过程 | BI8: aFRR上激活现金计算过程 | BJ8: aFRR下激活现金计算过程 | BK8: 总现金计算过程
A9: =原始输入与口径!C9 -> 46235 | B9: =IF(ISNUMBER(原始输入与口径!H9),原始输入与口径!H9,"缺失") -> 179.01 | C9: =IF(ISNUMBER(原始输入与口径!R9),原始输入与口径!R9,"缺失") -> 66.224535 | D9: =IF(ISNUMBER(原始输入与口径!W9),原始输入与口径!W9,"缺失") -> 7.1274751 | E9: =IF(ISNUMBER(原始输入与口径!AB9),原始输入与口径!AB9,"缺失") -> 2.7061536 | F9: =IF(ISNUMBER(原始输入与口径!AG9),原始输入与口径!AG9,"缺失") -> 391.8358 | G9: =IF(ISNUMBER(原始输入与口径!AJ9),原始输入与口径!AJ9,"缺失") -> 0 | H9: ="未模拟" -> 未模拟 | I9: =原始输入与口径!CD9 -> 31.73913 | J9: =原始输入与口径!CE9 -> 34.934674 | K9: =原始输入与口径!BZ9 -> -24 | L9: =原始输入与口径!CK9 -> 40 | M9: =原始输入与口径!BT9 -> 24 | N9: =原始输入与口径!BJ9 -> 24 | O9: =M9*AF9*AC9 -> 2.5265829 | P9: =N9*AG9*AC9 -> 0 | Q9: =IF(K9=0,0,IF(ISNUMBER(B9),K9*B9*AC9,NA())) -> -1074.06 | R9: =IF(L9=0,0,IF(ISNUMBER(C9),L9*C9*AC9,NA())) -> 662.24535 | S9: =IF(M9=0,0,IF(ISNUMBER(D9),M9*D9*AC9,NA())) -> 42.76485 | T9: =IF(N9=0,0,IF(ISNUMBER(E9),N9*E9*AC9,NA())) -> 16.236922 | U9: =IF(O9=0,0,O9*F9) -> 990.00562 | V9: =IF(P9=0,0,-P9*G9) -> 0 | W9: =SUM(Q9:V9) -> 637.19274 | X9: =原始输入与口径!CP9 -> 637.19274 | Y9: =W9-X9 -> 0 | Z9: ="当日执行" -> 当日执行 | AA9: =IF(原始输入与口径!AW9,1,0) -> 1 | AB9: =IF(原始输入与口径!AY9,1,0) -> 1 | AC9: =原始输入与口径!$F$5 -> 0.25 | AD9: =原始输入与口径!CG9 -> 0.3125 | AE9: =原始输入与口径!BQ9 -> 0.13714286 | AF9: =IF(AA9=0,0,AJ9/(AH9*AC9)) -> 0.42109714 | AG9: =IF(AA9=0,0,AK9/(AI9*AC9)) -> 0 | AH9: =IF(ISNUMBER(原始输入与口径!T9),原始输入与口径!T9,"缺失") -> 175 | AI9: =IF(ISNUMBER(原始输入与口径!Y9),原始输入与口径!Y9,"缺失") -> 175 | AJ9: =IF(ISNUMBER(原始输入与口径!AI9),原始输入与口径!AI9,"缺失") -> 18.423 | AK9: =IF(ISNUMBER(原始输入与口径!AL9),原始输入与口径!AL9,"缺失") -> 0 | AL9: =IF(ISNUMBER(原始输入与口径!O9),原始输入与口径!O9,"缺失") -> 131.968 | AM9: =SUMIFS(相位SOC复算!$N$9:$N$929,相位SOC复算!$S$9:$S$929,1) -> 0.0088765105 | AN9: =SUMIFS(相位SOC复算!$Q$9:$Q$929,相位SOC复算!$S$9:$S$929,1) -> 3.4734171 | AO9: =SUMIFS(相位SOC复算!$R$9:$R$929,相位SOC复算!$S$9:$S$929,1) -> 1.9822498e-14 | AP9: =相位SOC复算!J10 -> 34.934674 | AQ9: =AP9-J9 -> 0 | AR9: =IF(ISBLANK(原始输入与口径!M9),"",原始输入与口径!M9) -> 5.2473 | AS9: =IF(ISBLANK(原始输入与口径!L9),"",原始输入与口径!L9) -> 46234 | AT9: =IF(ISBLANK(原始输入与口径!A9),"",原始输入与口径!A9) -> 46234.875 | AU9: =IF(ISBLANK(原始输入与口径!I9),"",原始输入与口径!I9) -> 2026-07-31_93 | AV9: =IF(ISBLANK(原始输入与口径!J9),"",原始输入与口径!J9) -> 15 | AW9: =IF(ISBLANK(原始输入与口径!BB9),"",原始输入与口径!BB9) -> OK | AX9: =原始输入与口径!CI9 -> 128 | AY9: =原始输入与口径!BS9 -> 175 | AZ9: =原始输入与口径!BI9 -> 175 | BA9: =原始输入与口径!CM9 -> 40 | BB9: =原始输入与口径!BV9 -> 24 | BC9: =原始输入与口径!BL9 -> 24 | BD9: =46235 -> 46235 | BE9: =IF(K9=0,"零头寸，无结算现金",TEXT(K9,"0.000000")&" MW × "&TEXT(B9,"0.000000")&" × "&TEXT(AC9,"0.000000")&" h = "&TEXT(Q9,"0.000000")&" EUR") -> -24.000000 MW × 179.010000 × 0.250000 h = -1074.060000 EUR | BF9: =IF(L9=0,"零头寸，无结算现金",TEXT(L9,"0.000000")&" MW × "&TEXT(C9,"0.000000")&" × "&TEXT(AC9,"0.000000")&" h = "&TEXT(R9,"0.000000")&" EUR") -> 40.000000 MW × 66.224535 × 0.250000 h = 662.245345 EUR | BG9: =IF(M9=0,"零头寸，无结算现金",TEXT(M9,"0.000000")&" MW × "&TEXT(D9,"0.000000")&" × "&TEXT(AC9,"0.000000")&" h = "&TEXT(S9,"0.000000")&" EUR") -> 24.000000 MW × 7.127475 × 0.250000 h = 42.764850 EUR | BH9: =IF(N9=0,"零头寸，无结算现金",TEXT(N9,"0.000000")&" MW × "&TEXT(E9,"0.000000")&" × "&TEXT(AC9,"0.000000")&" h = "&TEXT(T9,"0.000000")&" EUR") -> 24.000000 MW × 2.706154 × 0.250000 h = 16.236922 EUR | BI9: =IF(O9=0,"零上调激活电量",TEXT(O9,"0.000000")&" MWh × "&TEXT(F9,"0.000000")&" = "&TEXT(U9,"0.000000")&" EUR") -> 2.526583 MWh × 391.835801 = 990.005618 EUR | BJ9: =IF(P9=0,"零下调激活电量","−("&TEXT(P9,"0.000000")&" MWh × "&TEXT(G9,"0.000000")&") = "&TEXT(V9,"0.000000")&" EUR") -> 零下调激活电量 | BK9: =TEXT(Q9,"0.000000")&" + "&TEXT(R9,"0.000000")&" + "&TEXT(S9,"0.000000")&" + "&TEXT(T9,"0.000000")&" + "&TEXT(U9,"0.000000")&" + "&TEXT(V9,"0.000000")&" = "&TEXT(W9,"0.000000")&" EUR" -> -1074.060000 + 662.245345 + 42.764850 + 16.236922 + 990.005618 + 0.000000 = 637.192736 EUR
A10: =原始输入与口径!C10 -> 46235.01 | B10: =IF(ISNUMBER(原始输入与口径!H10),原始输入与口径!H10,"缺失") -> 170.12 | C10: =IF(ISNUMBER(原始输入与口径!R10),原始输入与口径!R10,"缺失") -> 66.224535 | D10: =IF(ISNUMBER(原始输入与口径!W10),原始输入与口径!W10,"缺失") -> 7.1274751 | E10: =IF(ISNUMBER(原始输入与口径!AB10),原始输入与口径!AB10,"缺失") -> 2.7061536 | F10: =IF(ISNUMBER(原始输入与口径!AG10),原始输入与口径!AG10,"缺失") -> 264.63515 | G10: =IF(ISNUMBER(原始输入与口径!AJ10),原始输入与口径!AJ10,"缺失") -> 0 | H10: ="未模拟" -> 未模拟 | I10: =原始输入与口径!CD10 -> 34.934674 | J10: =原始输入与口径!CE10 -> 32.633208 | K10: =原始输入与口径!BZ10 -> 0 | L10: =原始输入与口径!CK10 -> 40 | M10: =原始输入与口径!BT10 -> 24 | N10: =原始输入与口径!BJ10 -> 24 | O10: =M10*AF10*AC10 -> 2.1173486 | P10: =N10*AG10*AC10 -> 0 | Q10: =IF(K10=0,0,IF(ISNUMBER(B10),K10*B10*AC10,NA())) -> 0 | R10: =IF(L10=0,0,IF(ISNUMBER(C10),L10*C10*AC10,NA())) -> 662.24535 | S10: =IF(M10=0,0,IF(ISNUMBER(D10),M10*D10*AC10,NA())) -> 42.76485 | T10: =IF(N10=0,0,IF(ISNUMBER(E10),N10*E10*AC10,NA())) -> 16.236922 | U10: =IF(O10=0,0,O10*F10) -> 560.32485 | V10: =IF(P10=0,0,-P10*G10) -> 0 | W10: =SUM(Q10:V10) -> 1281.572 | X10: =原始输入与口径!CP10 -> 1281.572 | Y10: =W10-X10 -> 0 | Z10: ="当日执行" -> 当日执行 | AA10: =IF(原始输入与口径!AW10,1,0) -> 1 | AB10: =IF(原始输入与口径!AY10,1,0) -> 1 | AC10: =原始输入与口径!$F$5 -> 0.25 | AD10: =原始输入与口径!CG10 -> 0.3125 | AE10: =原始输入与口径!BQ10 -> 0.13714286 | AF10: =IF(AA10=0,0,AJ10/(AH10*AC10)) -> 0.35289143 | AG10: =IF(AA10=0,0,AK10/(AI10*AC10)) -> 0 | AH10: =IF(ISNUMBER(原始输入与口径!T10),原始输入与口径!T10,"缺失") -> 175 | AI10: =IF(ISNUMBER(原始输入与口径!Y10),原始输入与口径!Y10,"缺失") -> 175 | AJ10: =IF(ISNUMBER(原始输入与口径!AI10),原始输入与口径!AI10,"缺失") -> 15.439 | AK10: =IF(ISNUMBER(原始输入与口径!AL10),原始输入与口径!AL10,"缺失") -> 0 | AL10: =IF(ISNUMBER(原始输入与口径!O10),原始输入与口径!O10,"缺失") -> 131.968 | AM10: =SUMIFS(相位SOC复算!$N$9:$N$929,相位SOC复算!$S$9:$S$929,2) -> 0.0063929607 | AN10: =SUMIFS(相位SOC复算!$Q$9:$Q$929,相位SOC复算!$S$9:$S$929,2) -> 0 | AO10: =SUMIFS(相位SOC复算!$R$9:$R$929,相位SOC复算!$S$9:$S$929,2) -> 2.1173486 | AP10: =相位SOC复算!J12 -> 32.633208 | AQ10: =AP10-J10 -> 0 | AR10: =IF(ISBLANK(原始输入与口径!M10),"",原始输入与口径!M10) -> 5.2473 | AS10: =IF(ISBLANK(原始输入与口径!L10),"",原始输入与口径!L10) -> 46234 | AT10: =IF(ISBLANK(原始输入与口径!A10),"",原始输入与口径!A10) -> 46234.885 | AU10: =IF(ISBLANK(原始输入与口径!I10),"",原始输入与口径!I10) -> 2026-07-31_94 | AV10: =IF(ISBLANK(原始输入与口径!J10),"",原始输入与口径!J10) -> 15 | AW10: =IF(ISBLANK(原始输入与口径!BB10),"",原始输入与口径!BB10) -> OK | AX10: =原始输入与口径!CI10 -> 128 | AY10: =原始输入与口径!BS10 -> 175 | AZ10: =原始输入与口径!BI10 -> 175 | BA10: =原始输入与口径!CM10 -> 40 | BB10: =原始输入与口径!BV10 -> 24 | BC10: =原始输入与口径!BL10 -> 24 | BD10: =46235 -> 46235 | BE10: =IF(K10=0,"零头寸，无结算现金",TEXT(K10,"0.000000")&" MW × "&TEXT(B10,"0.000000")&" × "&TEXT(AC10,"0.000000")&" h = "&TEXT(Q10,"0.000000")&" EUR") -> 零头寸，无结算现金 | BF10: =IF(L10=0,"零头寸，无结算现金",TEXT(L10,"0.000000")&" MW × "&TEXT(C10,"0.000000")&" × "&TEXT(AC10,"0.000000")&" h = "&TEXT(R10,"0.000000")&" EUR") -> 40.000000 MW × 66.224535 × 0.250000 h = 662.245345 EUR | BG10: =IF(M10=0,"零头寸，无结算现金",TEXT(M10,"0.000000")&" MW × "&TEXT(D10,"0.000000")&" × "&TEXT(AC10,"0.000000")&" h = "&TEXT(S10,"0.000000")&" EUR") -> 24.000000 MW × 7.127475 × 0.250000 h = 42.764850 EUR | BH10: =IF(N10=0,"零头寸，无结算现金",TEXT(N10,"0.000000")&" MW × "&TEXT(E10,"0.000000")&" × "&TEXT(AC10,"0.000000")&" h = "&TEXT(T10,"0.000000")&" EUR") -> 24.000000 MW × 2.706154 × 0.250000 h = 16.236922 EUR | BI10: =IF(O10=0,"零上调激活电量",TEXT(O10,"0.000000")&" MWh × "&TEXT(F10,"0.000000")&" = "&TEXT(U10,"0.000000")&" EUR") -> 2.117349 MWh × 264.635146 = 560.324848 EUR | BJ10: =IF(P10=0,"零下调激活电量","−("&TEXT(P10,"0.000000")&" MWh × "&TEXT(G10,"0.000000")&") = "&TEXT(V10,"0.000000")&" EUR") -> 零下调激活电量 | BK10: =TEXT(Q10,"0.000000")&" + "&TEXT(R10,"0.000000")&" + "&TEXT(S10,"0.000000")&" + "&TEXT(T10,"0.000000")&" + "&TEXT(U10,"0.000000")&" + "&TEXT(V10,"0.000000")&" = "&TEXT(W10,"0.000000")&" EUR" -> 0.000000 + 662.245345 + 42.764850 + 16.236922 + 560.324848 + 0.000000 = 1281.571965 EUR
A11: =原始输入与口径!C11 -> 46235.021 | B11: =IF(ISNUMBER(原始输入与口径!H11),原始输入与口径!H11,"缺失") -> 167.36 | C11: =IF(ISNUMBER(原始输入与口径!R11),原始输入与口径!R11,"缺失") -> 66.224535 | D11: =IF(ISNUMBER(原始输入与口径!W11),原始输入与口径!W11,"缺失") -> 7.1274751 | E11: =IF(ISNUMBER(原始输入与口径!AB11),原始输入与口径!AB11,"缺失") -> 2.7061536 | F11: =IF(ISNUMBER(原始输入与口径!AG11),原始输入与口径!AG11,"缺失") -> 422.70215 | G11: =IF(ISNUMBER(原始输入与口径!AJ11),原始输入与口径!AJ11,"缺失") -> 0 | H11: ="未模拟" -> 未模拟 | I11: =原始输入与口径!CD11 -> 32.633208 | J11: =原始输入与口径!CE11 -> 35.143389 | K11: =原始输入与口径!BZ11 -> -24 | L11: =原始输入与口径!CK11 -> 40 | M11: =原始输入与口径!BT11 -> 24 | N11: =原始输入与口径!BJ11 -> 24 | O11: =M11*AF11*AC11 -> 3.2715429 | P11: =N11*AG11*AC11 -> 0 | Q11: =IF(K11=0,0,IF(ISNUMBER(B11),K11*B11*AC11,NA())) -> -1004.16 | R11: =IF(L11=0,0,IF(ISNUMBER(C11),L11*C11*AC11,NA())) -> 662.24535 | S11: =IF(M11=0,0,IF(ISNUMBER(D11),M11*D11*AC11,NA())) -> 42.76485 | T11: =IF(N11=0,0,IF(ISNUMBER(E11),N11*E11*AC11,NA())) -> 16.236922 | U11: =IF(O11=0,0,O11*F11) -> 1382.8882 | V11: =IF(P11=0,0,-P11*G11) -> 0 | W11: =SUM(Q11:V11) -> 1099.9753 | X11: =原始输入与口径!CP11 -> 1099.9753 | Y11: =W11-X11 -> 0 | Z11: ="当日执行" -> 当日执行 | AA11: =IF(原始输入与口径!AW11,1,0) -> 1 | AB11: =IF(原始输入与口径!AY11,1,0) -> 1 | AC11: =原始输入与口径!$F$5 -> 0.25 | AD11: =原始输入与口径!CG11 -> 0.3125 | AE11: =原始输入与口径!BQ11 -> 0.13714286 | AF11: =IF(AA11=0,0,AJ11/(AH11*AC11)) -> 0.54525714 | AG11: =IF(AA11=0,0,AK11/(AI11*AC11)) -> 0 | AH11: =IF(ISNUMBER(原始输入与口径!T11),原始输入与口径!T11,"缺失") -> 175 | AI11: =IF(ISNUMBER(原始输入与口径!Y11),原始输入与口径!Y11,"缺失") -> 175 | AJ11: =IF(ISNUMBER(原始输入与口径!AI11),原始输入与口径!AI11,"缺失") -> 23.855 | AK11: =IF(ISNUMBER(原始输入与口径!AL11),原始输入与口径!AL11,"缺失") -> 0 | AL11: =IF(ISNUMBER(原始输入与口径!O11),原始输入与口径!O11,"缺失") -> 131.968 | AM11: =SUMIFS(相位SOC复算!$N$9:$N$929,相位SOC复算!$S$9:$S$929,3) -> 0.0069727238 | AN11: =SUMIFS(相位SOC复算!$Q$9:$Q$929,相位SOC复算!$S$9:$S$929,3) -> 2.7284571 | AO11: =SUMIFS(相位SOC复算!$R$9:$R$929,相位SOC复算!$S$9:$S$929,3) -> 0 | AP11: =相位SOC复算!J14 -> 35.143389 | AQ11: =AP11-J11 -> 0 | AR11: =IF(ISBLANK(原始输入与口径!M11),"",原始输入与口径!M11) -> 5.2473 | AS11: =IF(ISBLANK(原始输入与口径!L11),"",原始输入与口径!L11) -> 46234 | AT11: =IF(ISBLANK(原始输入与口径!A11),"",原始输入与口径!A11) -> 46234.896 | AU11: =IF(ISBLANK(原始输入与口径!I11),"",原始输入与口径!I11) -> 2026-07-31_95 | AV11: =IF(ISBLANK(原始输入与口径!J11),"",原始输入与口径!J11) -> 15 | AW11: =IF(ISBLANK(原始输入与口径!BB11),"",原始输入与口径!BB11) -> OK | AX11: =原始输入与口径!CI11 -> 128 | AY11: =原始输入与口径!BS11 -> 175 | AZ11: =原始输入与口径!BI11 -> 175 | BA11: =原始输入与口径!CM11 -> 40 | BB11: =原始输入与口径!BV11 -> 24 | BC11: =原始输入与口径!BL11 -> 24 | BD11: =46235 -> 46235 | BE11: =IF(K11=0,"零头寸，无结算现金",TEXT(K11,"0.000000")&" MW × "&TEXT(B11,"0.000000")&" × "&TEXT(AC11,"0.000000")&" h = "&TEXT(Q11,"0.000000")&" EUR") -> -24.000000 MW × 167.360000 × 0.250000 h = -1004.160000 EUR | BF11: =IF(L11=0,"零头寸，无结算现金",TEXT(L11,"0.000000")&" MW × "&TEXT(C11,"0.000000")&" × "&TEXT(AC11,"0.000000")&" h = "&TEXT(R11,"0.000000")&" EUR") -> 40.000000 MW × 66.224535 × 0.250000 h = 662.245345 EUR | BG11: =IF(M11=0,"零头寸，无结算现金",TEXT(M11,"0.000000")&" MW × "&TEXT(D11,"0.000000")&" × "&TEXT(AC11,"0.000000")&" h = "&TEXT(S11,"0.000000")&" EUR") -> 24.000000 MW × 7.127475 × 0.250000 h = 42.764850 EUR | BH11: =IF(N11=0,"零头寸，无结算现金",TEXT(N11,"0.000000")&" MW × "&TEXT(E11,"0.000000")&" × "&TEXT(AC11,"0.000000")&" h = "&TEXT(T11,"0.000000")&" EUR") -> 24.000000 MW × 2.706154 × 0.250000 h = 16.236922 EUR | BI11: =IF(O11=0,"零上调激活电量",TEXT(O11,"0.000000")&" MWh × "&TEXT(F11,"0.000000")&" = "&TEXT(U11,"0.000000")&" EUR") -> 3.271543 MWh × 422.702152 = 1382.888205 EUR | BJ11: =IF(P11=0,"零下调激活电量","−("&TEXT(P11,"0.000000")&" MWh × "&TEXT(G11,"0.000000")&") = "&TEXT(V11,"0.000000")&" EUR") -> 零下调激活电量 | BK11: =TEXT(Q11,"0.000000")&" + "&TEXT(R11,"0.000000")&" + "&TEXT(S11,"0.000000")&" + "&TEXT(T11,"0.000000")&" + "&TEXT(U11,"0.000000")&" + "&TEXT(V11,"0.000000")&" = "&TEXT(W11,"0.000000")&" EUR" -> -1004.160000 + 662.245345 + 42.764850 + 16.236922 + 1382.888205 + 0.000000 = 1099.975322 EUR
A12: =原始输入与口径!C12 -> 46235.031 | B12: =IF(ISNUMBER(原始输入与口径!H12),原始输入与口径!H12,"缺失") -> 165.13 | C12: =IF(ISNUMBER(原始输入与口径!R12),原始输入与口径!R12,"缺失") -> 66.224535 | D12: =IF(ISNUMBER(原始输入与口径!W12),原始输入与口径!W12,"缺失") -> 7.1274751 | E12: =IF(ISNUMBER(原始输入与口径!AB12),原始输入与口径!AB12,"缺失") -> 2.7061536 | F12: =IF(ISNUMBER(原始输入与口径!AG12),原始输入与口径!AG12,"缺失") -> 260.51455 | G12: =IF(ISNUMBER(原始输入与口径!AJ12),原始输入与口径!AJ12,"缺失") -> 76.261125 | H12: ="未模拟" -> 未模拟 | I12: =原始输入与口径!CD12 -> 35.143389 | J12: =原始输入与口径!CE12 -> 38.990356 | K12: =原始输入与口径!BZ12 -> -24 | L12: =原始输入与口径!CK12 -> 40 | M12: =原始输入与口径!BT12 -> 24 | N12: =原始输入与口径!BJ12 -> 24 | O12: =M12*AF12*AC12 -> 1.8865371 | P12: =N12*AG12*AC12 -> 0.068022857 | Q12: =IF(K12=0,0,IF(ISNUMBER(B12),K12*B12*AC12,NA())) -> -990.78 | R12: =IF(L12=0,0,IF(ISNUMBER(C12),L12*C12*AC12,NA())) -> 662.24535 | S12: =IF(M12=0,0,IF(ISNUMBER(D12),M12*D12*AC12,NA())) -> 42.76485 | T12: =IF(N12=0,0,IF(ISNUMBER(E12),N12*E12*AC12,NA())) -> 16.236922 | U12: =IF(O12=0,0,O12*F12) -> 491.47038 | V12: =IF(P12=0,0,-P12*G12) -> -5.1874996 | W12: =SUM(Q12:V12) -> 216.74999 | X12: =原始输入与口径!CP12 -> 216.74999 | Y12: =W12-X12 -> 0 | Z12: ="当日执行" -> 当日执行 | AA12: =IF(原始输入与口径!AW12,1,0) -> 1 | AB12: =IF(原始输入与口径!AY12,1,0) -> 1 | AC12: =原始输入与口径!$F$5 -> 0.25 | AD12: =原始输入与口径!CG12 -> 0.3125 | AE12: =原始输入与口径!BQ12 -> 0.13714286 | AF12: =IF(AA12=0,0,AJ12/(AH12*AC12)) -> 0.31442286 | AG12: =IF(AA12=0,0,AK12/(AI12*AC12)) -> 0.011337143 | AH12: =IF(ISNUMBER(原始输入与口径!T12),原始输入与口径!T12,"缺失") -> 175 | AI12: =IF(ISNUMBER(原始输入与口径!Y12),原始输入与口径!Y12,"缺失") -> 175 | AJ12: =IF(ISNUMBER(原始输入与口径!AI12),原始输入与口径!AI12,"缺失") -> 13.756 | AK12: =IF(ISNUMBER(原始输入与口径!AL12),原始输入与口径!AL12,"缺失") -> 0.496 | AL12: =IF(ISNUMBER(原始输入与口径!O12),原始输入与口径!O12,"缺失") -> 131.968 | AM12: =SUMIFS(相位SOC复算!$N$9:$N$929,相位SOC复算!$S$9:$S$929,4) -> 0.010686019 | AN12: =SUMIFS(相位SOC复算!$Q$9:$Q$929,相位SOC复算!$S$9:$S$929,4) -> 4.1814857 | AO12: =SUMIFS(相位SOC复算!$R$9:$R$929,相位SOC复算!$S$9:$S$929,4) -> 0 | AP12: =相位SOC复算!J17 -> 38.990356 | AQ12: =AP12-J12 -> 0 | AR12: =IF(ISBLANK(原始输入与口径!M12),"",原始输入与口径!M12) -> 5.2473 | AS12: =IF(ISBLANK(原始输入与口径!L12),"",原始输入与口径!L12) -> 46234 | AT12: =IF(ISBLANK(原始输入与口径!A12),"",原始输入与口径!A12) -> 46234.906 | AU12: =IF(ISBLANK(原始输入与口径!I12),"",原始输入与口径!I12) -> 2026-07-31_96 | AV12: =IF(ISBLANK(原始输入与口径!J12),"",原始输入与口径!J12) -> 15 | AW12: =IF(ISBLANK(原始输入与口径!BB12),"",原始输入与口径!BB12) -> OK | AX12: =原始输入与口径!CI12 -> 128 | AY12: =原始输入与口径!BS12 -> 175 | AZ12: =原始输入与口径!BI12 -> 175 | BA12: =原始输入与口径!CM12 -> 40 | BB12: =原始输入与口径!BV12 -> 24 | BC12: =原始输入与口径!BL12 -> 24 | BD12: =46235 -> 46235 | BE12: =IF(K12=0,"零头寸，无结算现金",TEXT(K12,"0.000000")&" MW × "&TEXT(B12,"0.000000")&" × "&TEXT(AC12,"0.000000")&" h = "&TEXT(Q12,"0.000000")&" EUR") -> -24.000000 MW × 165.130000 × 0.250000 h = -990.780000 EUR | BF12: =IF(L12=0,"零头寸，无结算现金",TEXT(L12,"0.000000")&" MW × "&TEXT(C12,"0.000000")&" × "&TEXT(AC12,"0.000000")&" h = "&TEXT(R12,"0.000000")&" EUR") -> 40.000000 MW × 66.224535 × 0.250000 h = 662.245345 EUR | BG12: =IF(M12=0,"零头寸，无结算现金",TEXT(M12,"0.000000")&" MW × "&TEXT(D12,"0.000000")&" × "&TEXT(AC12,"0.000000")&" h = "&TEXT(S12,"0.000000")&" EUR") -> 24.000000 MW × 7.127475 × 0.250000 h = 42.764850 EUR | BH12: =IF(N12=0,"零头寸，无结算现金",TEXT(N12,"0.000000")&" MW × "&TEXT(E12,"0.000000")&" × "&TEXT(AC12,"0.000000")&" h = "&TEXT(T12,"0.000000")&" EUR") -> 24.000000 MW × 2.706154 × 0.250000 h = 16.236922 EUR | BI12: =IF(O12=0,"零上调激活电量",TEXT(O12,"0.000000")&" MWh × "&TEXT(F12,"0.000000")&" = "&TEXT(U12,"0.000000")&" EUR") -> 1.886537 MWh × 260.514550 = 491.470375 EUR | BJ12: =IF(P12=0,"零下调激活电量","−("&TEXT(P12,"0.000000")&" MWh × "&TEXT(G12,"0.000000")&") = "&TEXT(V12,"0.000000")&" EUR") -> −(0.068023 MWh × 76.261125) = -5.187500 EUR | BK12: =TEXT(Q12,"0.000000")&" + "&TEXT(R12,"0.000000")&" + "&TEXT(S12,"0.000000")&" + "&TEXT(T12,"0.000000")&" + "&TEXT(U12,"0.000000")&" + "&TEXT(V12,"0.000000")&" = "&TEXT(W12,"0.000000")&" EUR" -> -990.780000 + 662.245345 + 42.764850 + 16.236922 + 491.470375 + -5.187500 = 216.749993 EUR
A13: =原始输入与口径!C13 -> 46235.042 | B13: =IF(ISNUMBER(原始输入与口径!H13),原始输入与口径!H13,"缺失") -> 184.32 | C13: =IF(ISNUMBER(原始输入与口径!R13),原始输入与口径!R13,"缺失") -> 66.224535 | D13: =IF(ISNUMBER(原始输入与口径!W13),原始输入与口径!W13,"缺失") -> 7.1274751 | E13: =IF(ISNUMBER(原始输入与口径!AB13),原始输入与口径!AB13,"缺失") -> 2.7061536 | F13: =IF(ISNUMBER(原始输入与口径!AG13),原始输入与口径!AG13,"缺失") -> 171.08894 | G13: =IF(ISNUMBER(原始输入与口径!AJ13),原始输入与口径!AJ13,"缺失") -> 74.70947 | H13: ="未模拟" -> 未模拟 | I13: =原始输入与口径!CD13 -> 38.990356 | J13: =原始输入与口径!CE13 -> 33.561199 | K13: =原始输入与口径!BZ13 -> 20.338412 | L13: =原始输入与口径!CK13 -> 40 | M13: =原始输入与口径!BT13 -> 24 | N13: =原始输入与口径!BJ13 -> 24 | O13: =M13*AF13*AC13 -> 0.14660571 | P13: =N13*AG13*AC13 -> 0.24205714 | Q13: =IF(K13=0,0,IF(ISNUMBER(B13),K13*B13*AC13,NA())) -> 937.19403 | R13: =IF(L13=0,0,IF(ISNUMBER(C13),L13*C13*AC13,NA())) -> 662.24535 | S13: =IF(M13=0,0,IF(ISNUMBER(D13),M13*D13*AC13,NA())) -> 42.76485 | T13: =IF(N13=0,0,IF(ISNUMBER(E13),N13*E13*AC13,NA())) -> 16.236922 | U13: =IF(O13=0,0,O13*F13) -> 25.082616 | V13: =IF(P13=0,0,-P13*G13) -> -18.083961 | W13: =SUM(Q13:V13) -> 1665.4398 | X13: =原始输入与口径!CP13 -> 1665.4398 | Y13: =W13-X13 -> 0 | Z13: ="当日执行" -> 当日执行 | AA13: =IF(原始输入与口径!AW13,1,0) -> 1 | AB13: =IF(原始输入与口径!AY13,1,0) -> 1 | AC13: =原始输入与口径!$F$5 -> 0.25 | AD13: =原始输入与口径!CG13 -> 0.3125 | AE13: =原始输入与口径!BQ13 -> 0.13714286 | AF13: =IF(AA13=0,0,AJ13/(AH13*AC13)) -> 0.024434286 | AG13: =IF(AA13=0,0,AK13/(AI13*AC13)) -> 0.040342857 | AH13: =IF(ISNUMBER(原始输入与口径!T13),原始输入与口径!T13,"缺失") -> 175 | AI13: =IF(ISNUMBER(原始输入与口径!Y13),原始输入与口径!Y13,"缺失") -> 175 | AJ13: =IF(ISNUMBER(原始输入与口径!AI13),原始输入与口径!AI13,"缺失") -> 1.069 | AK13: =IF(ISNUMBER(原始输入与口径!AL13),原始输入与口径!AL13,"缺失") -> 1.765 | AL13: =IF(ISNUMBER(原始输入与口径!O13),原始输入与口径!O13,"缺失") -> 128 | AM13: =SUMIFS(相位SOC复算!$N$9:$N$929,相位SOC复算!$S$9:$S$929,5) -> 0.015269742 | AN13: =SUMIFS(相位SOC复算!$Q$9:$Q$929,相位SOC复算!$S$9:$S$929,5) -> 0.036929729 | AO13: =SUMIFS(相位SOC复算!$R$9:$R$929,相位SOC复算!$S$9:$S$929,5) -> 5.0260813 | AP13: =相位SOC复算!J20 -> 33.561199 | AQ13: =AP13-J13 -> 0 | AR13: =IF(ISBLANK(原始输入与口径!M13),"",原始输入与口径!M13) -> 5.2473 | AS13: =IF(ISBLANK(原始输入与口径!L13),"",原始输入与口径!L13) -> 46234 | AT13: =IF(ISBLANK(原始输入与口径!A13),"",原始输入与口径!A13) -> 46234.917 | AU13: =IF(ISBLANK(原始输入与口径!I13),"",原始输入与口径!I13) -> 2026-08-01_1 | AV13: =IF(ISBLANK(原始输入与口径!J13),"",原始输入与口径!J13) -> 15 | AW13: =IF(ISBLANK(原始输入与口径!BB13),"",原始输入与口径!BB13) -> OK | AX13: =原始输入与口径!CI13 -> 128 | AY13: =原始输入与口径!BS13 -> 175 | AZ13: =原始输入与口径!BI13 -> 175 | BA13: =原始输入与口径!CM13 -> 40 | BB13: =原始输入与口径!BV13 -> 24 | BC13: =原始输入与口径!BL13 -> 24 | BD13: =46235 -> 46235 | BE13: =IF(K13=0,"零头寸，无结算现金",TEXT(K13,"0.000000")&" MW × "&TEXT(B13,"0.000000")&" × "&TEXT(AC13,"0.000000")&" h = "&TEXT(Q13,"0.000000")&" EUR") -> 20.338412 MW × 184.320000 × 0.250000 h = 937.194033 EUR | BF13: =IF(L13=0,"零头寸，无结算现金",TEXT(L13,"0.000000")&" MW × "&TEXT(C13,"0.000000")&" × "&TEXT(AC13,"0.000000")&" h = "&TEXT(R13,"0.000000")&" EUR") -> 40.000000 MW × 66.224535 × 0.250000 h = 662.245345 EUR | BG13: =IF(M13=0,"零头寸，无结算现金",TEXT(M13,"0.000000")&" MW × "&TEXT(D13,"0.000000")&" × "&TEXT(AC13,"0.000000")&" h = "&TEXT(S13,"0.000000")&" EUR") -> 24.000000 MW × 7.127475 × 0.250000 h = 42.764850 EUR | BH13: =IF(N13=0,"零头寸，无结算现金",TEXT(N13,"0.000000")&" MW × "&TEXT(E13,"0.000000")&" × "&TEXT(AC13,"0.000000")&" h = "&TEXT(T13,"0.000000")&" EUR") -> 24.000000 MW × 2.706154 × 0.250000 h = 16.236922 EUR | BI13: =IF(O13=0,"零上调激活电量",TEXT(O13,"0.000000")&" MWh × "&TEXT(F13,"0.000000")&" = "&TEXT(U13,"0.000000")&" EUR") -> 0.146606 MWh × 171.088941 = 25.082616 EUR | BJ13: =IF(P13=0,"零下调激活电量","−("&TEXT(P13,"0.000000")&" MWh × "&TEXT(G13,"0.000000")&") = "&TEXT(V13,"0.000000")&" EUR") -> −(0.242057 MWh × 74.709470) = -18.083961 EUR | BK13: =TEXT(Q13,"0.000000")&" + "&TEXT(R13,"0.000000")&" + "&TEXT(S13,"0.000000")&" + "&TEXT(T13,"0.000000")&" + "&TEXT(U13,"0.000000")&" + "&TEXT(V13,"0.000000")&" = "&TEXT(W13,"0.000000")&" EUR" -> 937.194033 + 662.245345 + 42.764850 + 16.236922 + 25.082616 + -18.083961 = 1665.439807 EUR
A14: =原始输入与口径!C14 -> 46235.052 | B14: =IF(ISNUMBER(原始输入与口径!H14),原始输入与口径!H14,"缺失") -> 174.23 | C14: =IF(ISNUMBER(原始输入与口径!R14),原始输入与口径!R14,"缺失") -> 66.224535 | D14: =IF(ISNUMBER(原始输入与口径!W14),原始输入与口径!W14,"缺失") -> 7.1274751 | E14: =IF(ISNUMBER(原始输入与口径!AB14),原始输入与口径!AB14,"缺失") -> 2.7061536 | F14: =IF(ISNUMBER(原始输入与口径!AG14),原始输入与口径!AG14,"缺失") -> 190.53685 | G14: =IF(ISNUMBER(原始输入与口径!AJ14),原始输入与口径!AJ14,"缺失") -> 0 | H14: ="未模拟" -> 未模拟 | I14: =原始输入与口径!CD14 -> 33.561199 | J14: =原始输入与口径!CE14 -> 32.71941 | K14: =原始输入与口径!BZ14 -> 0 | L14: =原始输入与口径!CK14 -> 40 | M14: =原始输入与口径!BT14 -> 24 | N14: =原始输入与口径!BJ14 -> 24 | O14: =M14*AF14*AC14 -> 0.77444571 | P14: =N14*AG14*AC14 -> 0 | Q14: =IF(K14=0,0,IF(ISNUMBER(B14),K14*B14*AC14,NA())) -> 0 | R14: =IF(L14=0,0,IF(ISNUMBER(C14),L14*C14*AC14,NA())) -> 662.24535 | S14: =IF(M14=0,0,IF(ISNUMBER(D14),M14*D14*AC14,NA())) -> 42.76485 | T14: =IF(N14=0,0,IF(ISNUMBER(E14),N14*E14*AC14,NA())) -> 16.236922 | U14: =IF(O14=0,0,O14*F14) -> 147.56044 | V14: =IF(P14=0,0,-P14*G14) -> 0 | W14: =SUM(Q14:V14) -> 868.80756 | X14: =原始输入与口径!CP14 -> 868.80756 | Y14: =W14-X14 -> 0 | Z14: ="当日执行" -> 当日执行 | AA14: =IF(原始输入与口径!AW14,1,0) -> 1 | AB14: =IF(原始输入与口径!AY14,1,0) -> 1 | AC14: =原始输入与口径!$F$5 -> 0.25 | AD14: =原始输入与口径!CG14 -> 0.3125 | AE14: =原始输入与口径!BQ14 -> 0.13714286 | AF14: =IF(AA14=0,0,AJ14/(AH14*AC14)) -> 0.12907429 | AG14: =IF(AA14=0,0,AK14/(AI14*AC14)) -> 0 | AH14: =IF(ISNUMBER(原始输入与口径!T14),原始输入与口径!T14,"缺失") -> 175 | AI14: =IF(ISNUMBER(原始输入与口径!Y14),原始输入与口径!Y14,"缺失") -> 175 | AJ14: =IF(ISNUMBER(原始输入与口径!AI14),原始输入与口径!AI14,"缺失") -> 5.647 | AK14: =IF(ISNUMBER(原始输入与口径!AL14),原始输入与口径!AL14,"缺失") -> 0 | AL14: =IF(ISNUMBER(原始输入与口径!O14),原始输入与口径!O14,"缺失") -> 128 | AM14: =SUMIFS(相位SOC复算!$N$9:$N$929,相位SOC复算!$S$9:$S$929,6) -> 0.0023383023 | AN14: =SUMIFS(相位SOC复算!$Q$9:$Q$929,相位SOC复算!$S$9:$S$929,6) -> 0 | AO14: =SUMIFS(相位SOC复算!$R$9:$R$929,相位SOC复算!$S$9:$S$929,6) -> 0.77444571 | AP14: =相位SOC复算!J22 -> 32.71941 | AQ14: =AP14-J14 -> 0 | AR14: =IF(ISBLANK(原始输入与口径!M14),"",原始输入与口径!M14) -> 5.2473 | AS14: =IF(ISBLANK(原始输入与口径!L14),"",原始输入与口径!L14) -> 46234 | AT14: =IF(ISBLANK(原始输入与口径!A14),"",原始输入与口径!A14) -> 46234.927 | AU14: =IF(ISBLANK(原始输入与口径!I14),"",原始输入与口径!I14) -> 2026-08-01_2 | AV14: =IF(ISBLANK(原始输入与口径!J14),"",原始输入与口径!J14) -> 15 | AW14: =IF(ISBLANK(原始输入与口径!BB14),"",原始输入与口径!BB14) -> OK | AX14: =原始输入与口径!CI14 -> 128 | AY14: =原始输入与口径!BS14 -> 175 | AZ14: =原始输入与口径!BI14 -> 175 | BA14: =原始输入与口径!CM14 -> 40 | BB14: =原始输入与口径!BV14 -> 24 | BC14: =原始输入与口径!BL14 -> 24 | BD14: =46235 -> 46235 | BE14: =IF(K14=0,"零头寸，无结算现金",TEXT(K14,"0.000000")&" MW × "&TEXT(B14,"0.000000")&" × "&TEXT(AC14,"0.000000")&" h = "&TEXT(Q14,"0.000000")&" EUR") -> 零头寸，无结算现金 | BF14: =IF(L14=0,"零头寸，无结算现金",TEXT(L14,"0.000000")&" MW × "&TEXT(C14,"0.000000")&" × "&TEXT(AC14,"0.000000")&" h = "&TEXT(R14,"0.000000")&" EUR") -> 40.000000 MW × 66.224535 × 0.250000 h = 662.245345 EUR | BG14: =IF(M14=0,"零头寸，无结算现金",TEXT(M14,"0.000000")&" MW × "&TEXT(D14,"0.000000")&" × "&TEXT(AC14,"0.000000")&" h = "&TEXT(S14,"0.000000")&" EUR") -> 24.000000 MW × 7.127475 × 0.250000 h = 42.764850 EUR | BH14: =IF(N14=0,"零头寸，无结算现金",TEXT(N14,"0.000000")&" MW × "&TEXT(E14,"0.000000")&" × "&TEXT(AC14,"0.000000")&" h = "&TEXT(T14,"0.000000")&" EUR") -> 24.000000 MW × 2.706154 × 0.250000 h = 16.236922 EUR | BI14: =IF(O14=0,"零上调激活电量",TEXT(O14,"0.000000")&" MWh × "&TEXT(F14,"0.000000")&" = "&TEXT(U14,"0.000000")&" EUR") -> 0.774446 MWh × 190.536848 = 147.560445 EUR | BJ14: =IF(P14=0,"零下调激活电量","−("&TEXT(P14,"0.000000")&" MWh × "&TEXT(G14,"0.000000")&") = "&TEXT(V14,"0.000000")&" EUR") -> 零下调激活电量 | BK14: =TEXT(Q14,"0.000000")&" + "&TEXT(R14,"0.000000")&" + "&TEXT(S14,"0.000000")&" + "&TEXT(T14,"0.000000")&" + "&TEXT(U14,"0.000000")&" + "&TEXT(V14,"0.000000")&" = "&TEXT(W14,"0.000000")&" EUR" -> 0.000000 + 662.245345 + 42.764850 + 16.236922 + 147.560445 + 0.000000 = 868.807563 EUR
A15: =原始输入与口径!C15 -> 46235.062 | B15: =IF(ISNUMBER(原始输入与口径!H15),原始输入与口径!H15,"缺失") -> 165.3 | C15: =IF(ISNUMBER(原始输入与口径!R15),原始输入与口径!R15,"缺失") -> 66.224535 | D15: =IF(ISNUMBER(原始输入与口径!W15),原始输入与口径!W15,"缺失") -> 7.1274751 | E15: =IF(ISNUMBER(原始输入与口径!AB15),原始输入与口径!AB15,"缺失") -> 2.7061536 | F15: =IF(ISNUMBER(原始输入与口径!AG15),原始输入与口径!AG15,"缺失") -> 181.55185 | G15: =IF(ISNUMBER(原始输入与口径!AJ15),原始输入与口径!AJ15,"缺失") -> 0 | H15: ="未模拟" -> 未模拟 | I15: =原始输入与口径!CD15 -> 32.71941 | J15: =原始输入与口径!CE15 -> 31.771336 | K15: =原始输入与口径!BZ15 -> 0 | L15: =原始输入与口径!CK15 -> 40 | M15: =原始输入与口径!BT15 -> 24 | N15: =原始输入与口径!BJ15 -> 24 | O15: =M15*AF15*AC15 -> 0.87222857 | P15: =N15*AG15*AC15 -> 0 | Q15: =IF(K15=0,0,IF(ISNUMBER(B15),K15*B15*AC15,NA())) -> 0 | R15: =IF(L15=0,0,IF(ISNUMBER(C15),L15*C15*AC15,NA())) -> 662.24535 | S15: =IF(M15=0,0,IF(ISNUMBER(D15),M15*D15*AC15,NA())) -> 42.76485 | T15: =IF(N15=0,0,IF(ISNUMBER(E15),N15*E15*AC15,NA())) -> 16.236922 | U15: =IF(O15=0,0,O15*F15) -> 158.35471 | V15: =IF(P15=0,0,-P15*G15) -> 0 | W15: =SUM(Q15:V15) -> 879.60182 | X15: =原始输入与口径!CP15 -> 879.60182 | Y15: =W15-X15 -> 0 | Z15: ="当日执行" -> 当日执行 | AA15: =IF(原始输入与口径!AW15,1,0) -> 1 | AB15: =IF(原始输入与口径!AY15,1,0) -> 1 | AC15: =原始输入与口径!$F$5 -> 0.25 | AD15: =原始输入与口径!CG15 -> 0.3125 | AE15: =原始输入与口径!BQ15 -> 0.13714286 | AF15: =IF(AA15=0,0,AJ15/(AH15*AC15)) -> 0.14537143 | AG15: =IF(AA15=0,0,AK15/(AI15*AC15)) -> 0 | AH15: =IF(ISNUMBER(原始输入与口径!T15),原始输入与口径!T15,"缺失") -> 175 | AI15: =IF(ISNUMBER(原始输入与口径!Y15),原始输入与口径!Y15,"缺失") -> 175 | AJ15: =IF(ISNUMBER(原始输入与口径!AI15),原始输入与口径!AI15,"缺失") -> 6.36 | AK15: =IF(ISNUMBER(原始输入与口径!AL15),原始输入与口径!AL15,"缺失") -> 0 | AL15: =IF(ISNUMBER(原始输入与口径!O15),原始输入与口径!O15,"缺失") -> 128 | AM15: =SUMIFS(相位SOC复算!$N$9:$N$929,相位SOC复算!$S$9:$S$929,7) -> 0.0026335404 | AN15: =SUMIFS(相位SOC复算!$Q$9:$Q$929,相位SOC复算!$S$9:$S$929,7) -> 0 | AO15: =SUMIFS(相位SOC复算!$R$9:$R$929,相位SOC复算!$S$9:$S$929,7) -> 0.87222857 | AP15: =相位SOC复算!J24 -> 31.771336 | AQ15: =AP15-J15 -> 0 | AR15: =IF(ISBLANK(原始输入与口径!M15),"",原始输入与口径!M15) -> 5.2473 | AS15: =IF(ISBLANK(原始输入与口径!L15),"",原始输入与口径!L15) -> 46234 | AT15: =IF(ISBLANK(原始输入与口径!A15),"",原始输入与口径!A15) -> 46234.938 | AU15: =IF(ISBLANK(原始输入与口径!I15),"",原始输入与口径!I15) -> 2026-08-01_3 | AV15: =IF(ISBLANK(原始输入与口径!J15),"",原始输入与口径!J15) -> 15 | AW15: =IF(ISBLANK(原始输入与口径!BB15),"",原始输入与口径!BB15) -> OK | AX15: =原始输入与口径!CI15 -> 128 | AY15: =原始输入与口径!BS15 -> 175 | AZ15: =原始输入与口径!BI15 -> 175 | BA15: =原始输入与口径!CM15 -> 40 | BB15: =原始输入与口径!BV15 -> 24 | BC15: =原始输入与口径!BL15 -> 24 | BD15: =46235 -> 46235 | BE15: =IF(K15=0,"零头寸，无结算现金",TEXT(K15,"0.000000")&" MW × "&TEXT(B15,"0.000000")&" × "&TEXT(AC15,"0.000000")&" h = "&TEXT(Q15,"0.000000")&" EUR") -> 零头寸，无结算现金 | BF15: =IF(L15=0,"零头寸，无结算现金",TEXT(L15,"0.000000")&" MW × "&TEXT(C15,"0.000000")&" × "&TEXT(AC15,"0.000000")&" h = "&TEXT(R15,"0.000000")&" EUR") -> 40.000000 MW × 66.224535 × 0.250000 h = 662.245345 EUR | BG15: =IF(M15=0,"零头寸，无结算现金",TEXT(M15,"0.000000")&" MW × "&TEXT(D15,"0.000000")&" × "&TEXT(AC15,"0.000000")&" h = "&TEXT(S15,"0.000000")&" EUR") -> 24.000000 MW × 7.127475 × 0.250000 h = 42.764850 EUR | BH15: =IF(N15=0,"零头寸，无结算现金",TEXT(N15,"0.000000")&" MW × "&TEXT(E15,"0.000000")&" × "&TEXT(AC15,"0.000000")&" h = "&TEXT(T15,"0.000000")&" EUR") -> 24.000000 MW × 2.706154 × 0.250000 h = 16.236922 EUR | BI15: =IF(O15=0,"零上调激活电量",TEXT(O15,"0.000000")&" MWh × "&TEXT(F15,"0.000000")&" = "&TEXT(U15,"0.000000")&" EUR") -> 0.872229 MWh × 181.551846 = 158.354707 EUR | BJ15: =IF(P15=0,"零下调激活电量","−("&TEXT(P15,"0.000000")&" MWh × "&TEXT(G15,"0.000000")&") = "&TEXT(V15,"0.000000")&" EUR") -> 零下调激活电量 | BK15: =TEXT(Q15,"0.000000")&" + "&TEXT(R15,"0.000000")&" + "&TEXT(S15,"0.000000")&" + "&TEXT(T15,"0.000000")&" + "&TEXT(U15,"0.000000")&" + "&TEXT(V15,"0.000000")&" = "&TEXT(W15,"0.000000")&" EUR" -> 0.000000 + 662.245345 + 42.764850 + 16.236922 + 158.354707 + 0.000000 = 879.601825 EUR
A16: =原始输入与口径!C16 -> 46235.073 | B16: =IF(ISNUMBER(原始输入与口径!H16),原始输入与口径!H16,"缺失") -> 157.23 | C16: =IF(ISNUMBER(原始输入与口径!R16),原始输入与口径!R16,"缺失") -> 66.224535 | D16: =IF(ISNUMBER(原始输入与口径!W16),原始输入与口径!W16,"缺失") -> 7.1274751 | E16: =IF(ISNUMBER(原始输入与口径!AB16),原始输入与口径!AB16,"缺失") -> 2.7061536 | F16: =IF(ISNUMBER(原始输入与口径!AG16),原始输入与口径!AG16,"缺失") -> 190.08785 | G16: =IF(ISNUMBER(原始输入与口径!AJ16),原始输入与口径!AJ16,"缺失") -> 0 | H16: ="未模拟" -> 未模拟 | I16: =原始输入与口径!CD16 -> 31.771336 | J16: =原始输入与口径!CE16 -> 36.483965 | K16: =原始输入与口径!BZ16 -> -24 | L16: =原始输入与口径!CK16 -> 40 | M16: =原始输入与口径!BT16 -> 24 | N16: =原始输入与口径!BJ16 -> 24 | O16: =M16*AF16*AC16 -> 0.87757714 | P16: =N16*AG16*AC16 -> 0 | Q16: =IF(K16=0,0,IF(ISNUMBER(B16),K16*B16*AC16,NA())) -> -943.38 | R16: =IF(L16=0,0,IF(ISNUMBER(C16),L16*C16*AC16,NA())) -> 662.24535 | S16: =IF(M16=0,0,IF(ISNUMBER(D16),M16*D16*AC16,NA())) -> 42.76485 | T16: =IF(N16=0,0,IF(ISNUMBER(E16),N16*E16*AC16,NA())) -> 16.236922 | U16: =IF(O16=0,0,O16*F16) -> 166.81676 | V16: =IF(P16=0,0,-P16*G16) -> 0 | W16: =SUM(Q16:V16) -> -55.316126 | X16: =原始输入与口径!CP16 -> -55.316126 | Y16: =W16-X16 -> 0 | Z16: ="当日执行" -> 当日执行 | AA16: =IF(原始输入与口径!AW16,1,0) -> 1 | AB16: =IF(原始输入与口径!AY16,1,0) -> 1 | AC16: =原始输入与口径!$F$5 -> 0.25 | AD16: =原始输入与口径!CG16 -> 0.3125 | AE16: =原始输入与口径!BQ16 -> 0.13714286 | AF16: =IF(AA16=0,0,AJ16/(AH16*AC16)) -> 0.14626286 | AG16: =IF(AA16=0,0,AK16/(AI16*AC16)) -> 0 | AH16: =IF(ISNUMBER(原始输入与口径!T16),原始输入与口径!T16,"缺失") -> 175 | AI16: =IF(ISNUMBER(原始输入与口径!Y16),原始输入与口径!Y16,"缺失") -> 175 | AJ16: =IF(ISNUMBER(原始输入与口径!AI16),原始输入与口径!AI16,"缺失") -> 6.399 | AK16: =IF(ISNUMBER(原始输入与口径!AL16),原始输入与口径!AL16,"缺失") -> 0 | AL16: =IF(ISNUMBER(原始输入与口径!O16),原始输入与口径!O16,"缺失") -> 128 | AM16: =SUMIFS(相位SOC复算!$N$9:$N$929,相位SOC复算!$S$9:$S$929,8) -> 0.013090636 | AN16: =SUMIFS(相位SOC复算!$Q$9:$Q$929,相位SOC复算!$S$9:$S$929,8) -> 5.1224229 | AO16: =SUMIFS(相位SOC复算!$R$9:$R$929,相位SOC复算!$S$9:$S$929,8) -> 0 | AP16: =相位SOC复算!J26 -> 36.483965 | AQ16: =AP16-J16 -> 0 | AR16: =IF(ISBLANK(原始输入与口径!M16),"",原始输入与口径!M16) -> 5.2473 | AS16: =IF(ISBLANK(原始输入与口径!L16),"",原始输入与口径!L16) -> 46234 | AT16: =IF(ISBLANK(原始输入与口径!A16),"",原始输入与口径!A16) -> 46234.948 | AU16: =IF(ISBLANK(原始输入与口径!I16),"",原始输入与口径!I16) -> 2026-08-01_4 | AV16: =IF(ISBLANK(原始输入与口径!J16),"",原始输入与口径!J16) -> 15 | AW16: =IF(ISBLANK(原始输入与口径!BB16),"",原始输入与口径!BB16) -> OK | AX16: =原始输入与口径!CI16 -> 128 | AY16: =原始输入与口径!BS16 -> 175 | AZ16: =原始输入与口径!BI16 -> 175 | BA16: =原始输入与口径!CM16 -> 40 | BB16: =原始输入与口径!BV16 -> 24 | BC16: =原始输入与口径!BL16 -> 24 | BD16: =46235 -> 46235 | BE16: =IF(K16=0,"零头寸，无结算现金",TEXT(K16,"0.000000")&" MW × "&TEXT(B16,"0.000000")&" × "&TEXT(AC16,"0.000000")&" h = "&TEXT(Q16,"0.000000")&" EUR") -> -24.000000 MW × 157.230000 × 0.250000 h = -943.380000 EUR | BF16: =IF(L16=0,"零头寸，无结算现金",TEXT(L16,"0.000000")&" MW × "&TEXT(C16,"0.000000")&" × "&TEXT(AC16,"0.000000")&" h = "&TEXT(R16,"0.000000")&" EUR") -> 40.000000 MW × 66.224535 × 0.250000 h = 662.245345 EUR | BG16: =IF(M16=0,"零头寸，无结算现金",TEXT(M16,"0.000000")&" MW × "&TEXT(D16,"0.000000")&" × "&TEXT(AC16,"0.000000")&" h = "&TEXT(S16,"0.000000")&" EUR") -> 24.000000 MW × 7.127475 × 0.250000 h = 42.764850 EUR | BH16: =IF(N16=0,"零头寸，无结算现金",TEXT(N16,"0.000000")&" MW × "&TEXT(E16,"0.000000")&" × "&TEXT(AC16,"0.000000")&" h = "&TEXT(T16,"0.000000")&" EUR") -> 24.000000 MW × 2.706154 × 0.250000 h = 16.236922 EUR | BI16: =IF(O16=0,"零上调激活电量",TEXT(O16,"0.000000")&" MWh × "&TEXT(F16,"0.000000")&" = "&TEXT(U16,"0.000000")&" EUR") -> 0.877577 MWh × 190.087855 = 166.816756 EUR | BJ16: =IF(P16=0,"零下调激活电量","−("&TEXT(P16,"0.000000")&" MWh × "&TEXT(G16,"0.000000")&") = "&TEXT(V16,"0.000000")&" EUR") -> 零下调激活电量 | BK16: =TEXT(Q16,"0.000000")&" + "&TEXT(R16,"0.000000")&" + "&TEXT(S16,"0.000000")&" + "&TEXT(T16,"0.000000")&" + "&TEXT(U16,"0.000000")&" + "&TEXT(V16,"0.000000")&" = "&TEXT(W16,"0.000000")&" EUR" -> -943.380000 + 662.245345 + 42.764850 + 16.236922 + 166.816756 + 0.000000 = -55.316126 EUR
A17: =原始输入与口径!C17 -> 46235.083 | B17: =IF(ISNUMBER(原始输入与口径!H17),原始输入与口径!H17,"缺失") -> 170.44 | C17: =IF(ISNUMBER(原始输入与口径!R17),原始输入与口径!R17,"缺失") -> 66.224535 | D17: =IF(ISNUMBER(原始输入与口径!W17),原始输入与口径!W17,"缺失") -> 7.1274751 | E17: =IF(ISNUMBER(原始输入与口径!AB17),原始输入与口径!AB17,"缺失") -> 2.7061536 | F17: =IF(ISNUMBER(原始输入与口径!AG17),原始输入与口径!AG17,"缺失") -> 227.42973 | G17: =IF(ISNUMBER(原始输入与口径!AJ17),原始输入与口径!AJ17,"缺失") -> 0 | H17: ="未模拟" -> 未模拟 | I17: =原始输入与口径!CD17 -> 36.483965 | J17: =原始输入与口径!CE17 -> 34.278648 | K17: =原始输入与口径!BZ17 -> 0 | L17: =原始输入与口径!CK17 -> 40 | M17: =原始输入与口径!BT17 -> 24 | N17: =原始输入与口径!BJ17 -> 24 | O17: =M17*AF17*AC17 -> 2.0288914 | P17: =N17*AG17*AC17 -> 0 | Q17: =IF(K17=0,0,IF(ISNUMBER(B17),K17*B17*AC17,NA())) -> 0 | R17: =IF(L17=0,0,IF(ISNUMBER(C17),L17*C17*AC17,NA())) -> 662.24535 | S17: =IF(M17=0,0,IF(ISNUMBER(D17),M17*D17*AC17,NA())) -> 42.76485 | T17: =IF(N17=0,0,IF(ISNUMBER(E17),N17*E17*AC17,NA())) -> 16.236922 | U17: =IF(O17=0,0,O17*F17) -> 461.43022 | V17: =IF(P17=0,0,-P17*G17) -> 0 | W17: =SUM(Q17:V17) -> 1182.6773 | X17: =原始输入与口径!CP17 -> 1182.6773 | Y17: =W17-X17 -> 0 | Z17: ="当日执行" -> 当日执行 | AA17: =IF(原始输入与口径!AW17,1,0) -> 1 | AB17: =IF(原始输入与口径!AY17,1,0) -> 1 | AC17: =原始输入与口径!$F$5 -> 0.25 | AD17: =原始输入与口径!CG17 -> 0.3125 | AE17: =原始输入与口径!BQ17 -> 0.13714286 | AF17: =IF(AA17=0,0,AJ17/(AH17*AC17)) -> 0.33814857 | AG17: =IF(AA17=0,0,AK17/(AI17*AC17)) -> 0 | AH17: =IF(ISNUMBER(原始输入与口径!T17),原始输入与口径!T17,"缺失") -> 175 | AI17: =IF(ISNUMBER(原始输入与口径!Y17),原始输入与口径!Y17,"缺失") -> 175 | AJ17: =IF(ISNUMBER(原始输入与口径!AI17),原始输入与口径!AI17,"缺失") -> 14.794 | AK17: =IF(ISNUMBER(原始输入与口径!AL17),原始输入与口径!AL17,"缺失") -> 0 | AL17: =IF(ISNUMBER(原始输入与口径!O17),原始输入与口径!O17,"缺失") -> 128 | AM17: =SUMIFS(相位SOC复算!$N$9:$N$929,相位SOC复算!$S$9:$S$929,9) -> 0.0061258799 | AN17: =SUMIFS(相位SOC复算!$Q$9:$Q$929,相位SOC复算!$S$9:$S$929,9) -> 0 | AO17: =SUMIFS(相位SOC复算!$R$9:$R$929,相位SOC复算!$S$9:$S$929,9) -> 2.0288914 | AP17: =相位SOC复算!J28 -> 34.278648 | AQ17: =AP17-J17 -> 0 | AR17: =IF(ISBLANK(原始输入与口径!M17),"",原始输入与口径!M17) -> 5.2473 | AS17: =IF(ISBLANK(原始输入与口径!L17),"",原始输入与口径!L17) -> 46234 | AT17: =IF(ISBLANK(原始输入与口径!A17),"",原始输入与口径!A17) -> 46234.958 | AU17: =IF(ISBLANK(原始输入与口径!I17),"",原始输入与口径!I17) -> 2026-08-01_5 | AV17: =IF(ISBLANK(原始输入与口径!J17),"",原始输入与口径!J17) -> 15 | AW17: =IF(ISBLANK(原始输入与口径!BB17),"",原始输入与口径!BB17) -> OK | AX17: =原始输入与口径!CI17 -> 128 | AY17: =原始输入与口径!BS17 -> 175 | AZ17: =原始输入与口径!BI17 -> 175 | BA17: =原始输入与口径!CM17 -> 40 | BB17: =原始输入与口径!BV17 -> 24 | BC17: =原始输入与口径!BL17 -> 24 | BD17: =46235 -> 46235 | BE17: =IF(K17=0,"零头寸，无结算现金",TEXT(K17,"0.000000")&" MW × "&TEXT(B17,"0.000000")&" × "&TEXT(AC17,"0.000000")&" h = "&TEXT(Q17,"0.000000")&" EUR") -> 零头寸，无结算现金 | BF17: =IF(L17=0,"零头寸，无结算现金",TEXT(L17,"0.000000")&" MW × "&TEXT(C17,"0.000000")&" × "&TEXT(AC17,"0.000000")&" h = "&TEXT(R17,"0.000000")&" EUR") -> 40.000000 MW × 66.224535 × 0.250000 h = 662.245345 EUR | BG17: =IF(M17=0,"零头寸，无结算现金",TEXT(M17,"0.000000")&" MW × "&TEXT(D17,"0.000000")&" × "&TEXT(AC17,"0.000000")&" h = "&TEXT(S17,"0.000000")&" EUR") -> 24.000000 MW × 7.127475 × 0.250000 h = 42.764850 EUR | BH17: =IF(N17=0,"零头寸，无结算现金",TEXT(N17,"0.000000")&" MW × "&TEXT(E17,"0.000000")&" × "&TEXT(AC17,"0.000000")&" h = "&TEXT(T17,"0.000000")&" EUR") -> 24.000000 MW × 2.706154 × 0.250000 h = 16.236922 EUR | BI17: =IF(O17=0,"零上调激活电量",TEXT(O17,"0.000000")&" MWh × "&TEXT(F17,"0.000000")&" = "&TEXT(U17,"0.000000")&" EUR") -> 2.028891 MWh × 227.429726 = 461.430221 EUR | BJ17: =IF(P17=0,"零下调激活电量","−("&TEXT(P17,"0.000000")&" MWh × "&TEXT(G17,"0.000000")&") = "&TEXT(V17,"0.000000")&" EUR") -> 零下调激活电量 | BK17: =TEXT(Q17,"0.000000")&" + "&TEXT(R17,"0.000000")&" + "&TEXT(S17,"0.000000")&" + "&TEXT(T17,"0.000000")&" + "&TEXT(U17,"0.000000")&" + "&TEXT(V17,"0.000000")&" = "&TEXT(W17,"0.000000")&" EUR" -> 0.000000 + 662.245345 + 42.764850 + 16.236922 + 461.430221 + 0.000000 = 1182.677339 EUR
